Watching for file changes with StatReloader
Performing system checks...

System check identified no issues (0 silenced).
February 07, 2024 - 03:56:51
Django version 4.2.9, using settings 'Skytronsystem.settings'
Starting development server at http://0.0.0.0:2000/
Quit the server with CONTROL-C.

/usr/local/lib/python3.8/dist-packages/django/db/models/fields/__init__.py:1535: RuntimeWarning: DateTimeField DeviceStock.esim_validity received a naive datetime (2024-03-01 00:00:00) while time zone support is active.
  warnings.warn(
[07/Feb/2024 03:57:01] "POST /api/devicestock/deviceStockFilter/ HTTP/1.1" 200 12
[07/Feb/2024 03:57:39] "POST /api/devicestock/deviceStockFilter/ HTTP/1.1" 200 12
[07/Feb/2024 03:57:52] "POST /api/devicestock/deviceStockFilter/ HTTP/1.1" 200 2136
[07/Feb/2024 03:58:27] "POST /api/devicestock/deviceStockFilter/ HTTP/1.1" 200 2136
[07/Feb/2024 03:59:02] "POST /api/devicestock/deviceStockFilter/ HTTP/1.1" 200 886
/var/www/html/skytron_backend/Skytronsystem/skytron_api/serializers.py changed, reloading.
Watching for file changes with StatReloader
Performing system checks...

System check identified no issues (0 silenced).
February 07, 2024 - 04:18:37
Django version 4.2.9, using settings 'Skytronsystem.settings'
Starting development server at http://0.0.0.0:2000/
Quit the server with CONTROL-C.

/var/www/html/skytron_backend/Skytronsystem/skytron_api/views.py changed, reloading.
Watching for file changes with StatReloader
Performing system checks...

System check identified no issues (0 silenced).
February 07, 2024 - 04:22:46
Django version 4.2.9, using settings 'Skytronsystem.settings'
Starting development server at http://0.0.0.0:2000/
Quit the server with CONTROL-C.

/var/www/html/skytron_backend/Skytronsystem/skytron_api/urls.py changed, reloading.
Watching for file changes with StatReloader
Performing system checks...

System check identified no issues (0 silenced).
February 07, 2024 - 04:23:33
Django version 4.2.9, using settings 'Skytronsystem.settings'
Starting development server at http://0.0.0.0:2000/
Quit the server with CONTROL-C.

Bad Request: /api/devicestock/StockAssignToRetailer/
[07/Feb/2024 04:29:13] "POST /api/devicestock/StockAssignToRetailer/ HTTP/1.1" 400 186
/var/www/html/skytron_backend/Skytronsystem/skytron_api/models.py changed, reloading.
Watching for file changes with StatReloader
Performing system checks...

System check identified no issues (0 silenced).
February 07, 2024 - 04:30:37
Django version 4.2.9, using settings 'Skytronsystem.settings'
Starting development server at http://0.0.0.0:2000/
Quit the server with CONTROL-C.

/var/www/html/skytron_backend/Skytronsystem/skytron_api/models.py changed, reloading.
Watching for file changes with StatReloader
Performing system checks...

System check identified no issues (0 silenced).
February 07, 2024 - 04:30:52
Django version 4.2.9, using settings 'Skytronsystem.settings'
Starting development server at http://0.0.0.0:2000/
Quit the server with CONTROL-C.

Bad Request: /api/devicestock/StockAssignToRetailer/
[07/Feb/2024 04:34:01] "POST /api/devicestock/StockAssignToRetailer/ HTTP/1.1" 400 133
Bad Request: /api/devicestock/StockAssignToRetailer/
[07/Feb/2024 04:34:46] "POST /api/devicestock/StockAssignToRetailer/ HTTP/1.1" 400 132
Bad Request: /api/devicestock/StockAssignToRetailer/
[07/Feb/2024 04:36:37] "POST /api/devicestock/StockAssignToRetailer/ HTTP/1.1" 400 132
Bad Request: /api/devicestock/StockAssignToRetailer/
[07/Feb/2024 04:38:15] "POST /api/devicestock/StockAssignToRetailer/ HTTP/1.1" 400 132
/var/www/html/skytron_backend/Skytronsystem/skytron_api/views.py changed, reloading.
Watching for file changes with StatReloader
Performing system checks...

System check identified no issues (0 silenced).
February 07, 2024 - 04:40:55
Django version 4.2.9, using settings 'Skytronsystem.settings'
Starting development server at http://0.0.0.0:2000/
Quit the server with CONTROL-C.

/var/www/html/skytron_backend/Skytronsystem/skytron_api/views.py changed, reloading.
Watching for file changes with StatReloader
Performing system checks...

System check identified no issues (0 silenced).
February 07, 2024 - 04:42:47
Django version 4.2.9, using settings 'Skytronsystem.settings'
Starting development server at http://0.0.0.0:2000/
Quit the server with CONTROL-C.

Internal Server Error: /api/devicestock/StockAssignToRetailer/
Traceback (most recent call last):
  File "/usr/local/lib/python3.8/dist-packages/django/core/handlers/exception.py", line 55, in inner
    response = get_response(request)
  File "/usr/local/lib/python3.8/dist-packages/django/core/handlers/base.py", line 197, in _get_response
    response = wrapped_callback(request, *callback_args, **callback_kwargs)
  File "/usr/local/lib/python3.8/dist-packages/django/views/decorators/csrf.py", line 56, in wrapper_view
    return view_func(*args, **kwargs)
  File "/usr/local/lib/python3.8/dist-packages/django/views/generic/base.py", line 104, in view
    return self.dispatch(request, *args, **kwargs)
  File "/usr/local/lib/python3.8/dist-packages/rest_framework/views.py", line 509, in dispatch
    response = self.handle_exception(exc)
  File "/usr/local/lib/python3.8/dist-packages/rest_framework/views.py", line 469, in handle_exception
    self.raise_uncaught_exception(exc)
  File "/usr/local/lib/python3.8/dist-packages/rest_framework/views.py", line 480, in raise_uncaught_exception
    raise exc
  File "/usr/local/lib/python3.8/dist-packages/rest_framework/views.py", line 506, in dispatch
    response = handler(request, *args, **kwargs)
  File "/usr/local/lib/python3.8/dist-packages/rest_framework/decorators.py", line 50, in handler
    return func(*args, **kwargs)
  File "/var/www/html/skytron_backend/Skytronsystem/skytron_api/views.py", line 104, in StockAssignToRetailer
    data['device'] = int(device_id)
ValueError: invalid literal for int() with base 10: '[1, 2, 3]'
[07/Feb/2024 04:42:56] "POST /api/devicestock/StockAssignToRetailer/ HTTP/1.1" 500 94031
/var/www/html/skytron_backend/Skytronsystem/skytron_api/views.py changed, reloading.
Watching for file changes with StatReloader
Performing system checks...

System check identified no issues (0 silenced).
February 07, 2024 - 04:53:27
Django version 4.2.9, using settings 'Skytronsystem.settings'
Starting development server at http://0.0.0.0:2000/
Quit the server with CONTROL-C.

Internal Server Error: /api/devicestock/StockAssignToRetailer/
Traceback (most recent call last):
  File "/usr/local/lib/python3.8/dist-packages/django/core/handlers/exception.py", line 55, in inner
    response = get_response(request)
  File "/usr/local/lib/python3.8/dist-packages/django/core/handlers/base.py", line 197, in _get_response
    response = wrapped_callback(request, *callback_args, **callback_kwargs)
  File "/usr/local/lib/python3.8/dist-packages/django/views/decorators/csrf.py", line 56, in wrapper_view
    return view_func(*args, **kwargs)
  File "/usr/local/lib/python3.8/dist-packages/django/views/generic/base.py", line 104, in view
    return self.dispatch(request, *args, **kwargs)
  File "/usr/local/lib/python3.8/dist-packages/rest_framework/views.py", line 509, in dispatch
    response = self.handle_exception(exc)
  File "/usr/local/lib/python3.8/dist-packages/rest_framework/views.py", line 469, in handle_exception
    self.raise_uncaught_exception(exc)
  File "/usr/local/lib/python3.8/dist-packages/rest_framework/views.py", line 480, in raise_uncaught_exception
    raise exc
  File "/usr/local/lib/python3.8/dist-packages/rest_framework/views.py", line 506, in dispatch
    response = handler(request, *args, **kwargs)
  File "/usr/local/lib/python3.8/dist-packages/rest_framework/decorators.py", line 50, in handler
    return func(*args, **kwargs)
  File "/var/www/html/skytron_backend/Skytronsystem/skytron_api/views.py", line 99, in StockAssignToRetailer
    device_ids = ast.literal_eval(data.pop('device', '[]'))
  File "/usr/lib/python3.8/ast.py", line 99, in literal_eval
    return _convert(node_or_string)
  File "/usr/lib/python3.8/ast.py", line 98, in _convert
    return _convert_signed_num(node)
  File "/usr/lib/python3.8/ast.py", line 75, in _convert_signed_num
    return _convert_num(node)
  File "/usr/lib/python3.8/ast.py", line 66, in _convert_num
    _raise_malformed_node(node)
  File "/usr/lib/python3.8/ast.py", line 63, in _raise_malformed_node
    raise ValueError(f'malformed node or string: {node!r}')
ValueError: malformed node or string: ['[1, 2, 3]']
[07/Feb/2024 04:53:33] "POST /api/devicestock/StockAssignToRetailer/ HTTP/1.1" 500 114025
/var/www/html/skytron_backend/Skytronsystem/skytron_api/views.py changed, reloading.
Watching for file changes with StatReloader
Performing system checks...

System check identified no issues (0 silenced).
February 07, 2024 - 04:54:08
Django version 4.2.9, using settings 'Skytronsystem.settings'
Starting development server at http://0.0.0.0:2000/
Quit the server with CONTROL-C.

Internal Server Error: /api/devicestock/StockAssignToRetailer/
Traceback (most recent call last):
  File "/usr/local/lib/python3.8/dist-packages/django/core/handlers/exception.py", line 55, in inner
    response = get_response(request)
  File "/usr/local/lib/python3.8/dist-packages/django/core/handlers/base.py", line 197, in _get_response
    response = wrapped_callback(request, *callback_args, **callback_kwargs)
  File "/usr/local/lib/python3.8/dist-packages/django/views/decorators/csrf.py", line 56, in wrapper_view
    return view_func(*args, **kwargs)
  File "/usr/local/lib/python3.8/dist-packages/django/views/generic/base.py", line 104, in view
    return self.dispatch(request, *args, **kwargs)
  File "/usr/local/lib/python3.8/dist-packages/rest_framework/views.py", line 509, in dispatch
    response = self.handle_exception(exc)
  File "/usr/local/lib/python3.8/dist-packages/rest_framework/views.py", line 469, in handle_exception
    self.raise_uncaught_exception(exc)
  File "/usr/local/lib/python3.8/dist-packages/rest_framework/views.py", line 480, in raise_uncaught_exception
    raise exc
  File "/usr/local/lib/python3.8/dist-packages/rest_framework/views.py", line 506, in dispatch
    response = handler(request, *args, **kwargs)
  File "/usr/local/lib/python3.8/dist-packages/rest_framework/decorators.py", line 50, in handler
    return func(*args, **kwargs)
  File "/var/www/html/skytron_backend/Skytronsystem/skytron_api/views.py", line 99, in StockAssignToRetailer
    device_ids = ast.literal_eval(data.pop('device'))
  File "/usr/lib/python3.8/ast.py", line 99, in literal_eval
    return _convert(node_or_string)
  File "/usr/lib/python3.8/ast.py", line 98, in _convert
    return _convert_signed_num(node)
  File "/usr/lib/python3.8/ast.py", line 75, in _convert_signed_num
    return _convert_num(node)
  File "/usr/lib/python3.8/ast.py", line 66, in _convert_num
    _raise_malformed_node(node)
  File "/usr/lib/python3.8/ast.py", line 63, in _raise_malformed_node
    raise ValueError(f'malformed node or string: {node!r}')
ValueError: malformed node or string: ['[1, 2, 3]']
[07/Feb/2024 04:54:11] "POST /api/devicestock/StockAssignToRetailer/ HTTP/1.1" 500 113993
/var/www/html/skytron_backend/Skytronsystem/skytron_api/views.py changed, reloading.
Watching for file changes with StatReloader
Performing system checks...

System check identified no issues (0 silenced).
February 07, 2024 - 04:55:17
Django version 4.2.9, using settings 'Skytronsystem.settings'
Starting development server at http://0.0.0.0:2000/
Quit the server with CONTROL-C.

Internal Server Error: /api/devicestock/StockAssignToRetailer/
Traceback (most recent call last):
  File "/usr/local/lib/python3.8/dist-packages/django/core/handlers/exception.py", line 55, in inner
    response = get_response(request)
  File "/usr/local/lib/python3.8/dist-packages/django/core/handlers/base.py", line 197, in _get_response
    response = wrapped_callback(request, *callback_args, **callback_kwargs)
  File "/usr/local/lib/python3.8/dist-packages/django/views/decorators/csrf.py", line 56, in wrapper_view
    return view_func(*args, **kwargs)
  File "/usr/local/lib/python3.8/dist-packages/django/views/generic/base.py", line 104, in view
    return self.dispatch(request, *args, **kwargs)
  File "/usr/local/lib/python3.8/dist-packages/rest_framework/views.py", line 509, in dispatch
    response = self.handle_exception(exc)
  File "/usr/local/lib/python3.8/dist-packages/rest_framework/views.py", line 469, in handle_exception
    self.raise_uncaught_exception(exc)
  File "/usr/local/lib/python3.8/dist-packages/rest_framework/views.py", line 480, in raise_uncaught_exception
    raise exc
  File "/usr/local/lib/python3.8/dist-packages/rest_framework/views.py", line 506, in dispatch
    response = handler(request, *args, **kwargs)
  File "/usr/local/lib/python3.8/dist-packages/rest_framework/decorators.py", line 50, in handler
    return func(*args, **kwargs)
  File "/var/www/html/skytron_backend/Skytronsystem/skytron_api/views.py", line 105, in StockAssignToRetailer
    data['device'] = int(device_id)
ValueError: invalid literal for int() with base 10: '[1, 2, 3]'
[07/Feb/2024 04:55:22] "POST /api/devicestock/StockAssignToRetailer/ HTTP/1.1" 500 94079
/var/www/html/skytron_backend/Skytronsystem/skytron_api/views.py changed, reloading.
Watching for file changes with StatReloader
Performing system checks...

System check identified no issues (0 silenced).
February 07, 2024 - 04:56:27
Django version 4.2.9, using settings 'Skytronsystem.settings'
Starting development server at http://0.0.0.0:2000/
Quit the server with CONTROL-C.

Bad Request: /api/devicestock/StockAssignToRetailer/
[07/Feb/2024 04:56:29] "POST /api/devicestock/StockAssignToRetailer/ HTTP/1.1" 400 68
Bad Request: /api/devicestock/StockAssignToRetailer/
[07/Feb/2024 04:58:37] "POST /api/devicestock/StockAssignToRetailer/ HTTP/1.1" 400 68
Forbidden: /api/list_retailers/
[07/Feb/2024 05:00:39] "GET /api/list_retailers/ HTTP/1.1" 403 58
[07/Feb/2024 05:01:17] "GET /api/list_retailers/ HTTP/1.1" 200 2
Bad Request: /api/create_retailer/
[07/Feb/2024 05:04:44] "POST /api/create_retailer/ HTTP/1.1" 400 112
Bad Request: /api/create_retailer/
[07/Feb/2024 05:06:15] "POST /api/create_retailer/ HTTP/1.1" 400 116
Bad Request: /api/create_retailer/
[07/Feb/2024 05:06:55] "POST /api/create_retailer/ HTTP/1.1" 400 117
[07/Feb/2024 05:07:13] "POST /api/create_retailer/ HTTP/1.1" 201 161
[07/Feb/2024 05:08:39] "POST /api/devicestock/StockAssignToRetailer/ HTTP/1.1" 201 623
/var/www/html/skytron_backend/Skytronsystem/skytron_api/urls.py changed, reloading.
Watching for file changes with StatReloader
Performing system checks...

Exception in thread django-main-thread:
Traceback (most recent call last):
  File "/usr/lib/python3.8/threading.py", line 932, in _bootstrap_inner
    self.run()
  File "/usr/lib/python3.8/threading.py", line 870, in run
    self._target(*self._args, **self._kwargs)
  File "/usr/local/lib/python3.8/dist-packages/django/utils/autoreload.py", line 64, in wrapper
    fn(*args, **kwargs)
  File "/usr/local/lib/python3.8/dist-packages/django/core/management/commands/runserver.py", line 133, in inner_run
    self.check(display_num_errors=True)
  File "/usr/local/lib/python3.8/dist-packages/django/core/management/base.py", line 485, in check
    all_issues = checks.run_checks(
  File "/usr/local/lib/python3.8/dist-packages/django/core/checks/registry.py", line 88, in run_checks
    new_errors = check(app_configs=app_configs, databases=databases)
  File "/usr/local/lib/python3.8/dist-packages/django/core/checks/urls.py", line 14, in check_url_config
    return check_resolver(resolver)
  File "/usr/local/lib/python3.8/dist-packages/django/core/checks/urls.py", line 24, in check_resolver
    return check_method()
  File "/usr/local/lib/python3.8/dist-packages/django/urls/resolvers.py", line 494, in check
    for pattern in self.url_patterns:
  File "/usr/local/lib/python3.8/dist-packages/django/utils/functional.py", line 57, in __get__
    res = instance.__dict__[self.name] = self.func(instance)
  File "/usr/local/lib/python3.8/dist-packages/django/urls/resolvers.py", line 715, in url_patterns
    patterns = getattr(self.urlconf_module, "urlpatterns", self.urlconf_module)
  File "/usr/local/lib/python3.8/dist-packages/django/utils/functional.py", line 57, in __get__
    res = instance.__dict__[self.name] = self.func(instance)
  File "/usr/local/lib/python3.8/dist-packages/django/urls/resolvers.py", line 708, in urlconf_module
    return import_module(self.urlconf_name)
  File "/usr/lib/python3.8/importlib/__init__.py", line 127, in import_module
    return _bootstrap._gcd_import(name[level:], package, level)
  File "<frozen importlib._bootstrap>", line 1014, in _gcd_import
  File "<frozen importlib._bootstrap>", line 991, in _find_and_load
  File "<frozen importlib._bootstrap>", line 975, in _find_and_load_unlocked
  File "<frozen importlib._bootstrap>", line 671, in _load_unlocked
  File "<frozen importlib._bootstrap_external>", line 848, in exec_module
  File "<frozen importlib._bootstrap>", line 219, in _call_with_frames_removed
  File "/var/www/html/skytron_backend/Skytronsystem/Skytronsystem/urls.py", line 24, in <module>
    path('api/', include('skytron_api.urls')),  # Include the skytron_api URLs
  File "/usr/local/lib/python3.8/dist-packages/django/urls/conf.py", line 38, in include
    urlconf_module = import_module(urlconf_module)
  File "/usr/lib/python3.8/importlib/__init__.py", line 127, in import_module
    return _bootstrap._gcd_import(name[level:], package, level)
  File "<frozen importlib._bootstrap>", line 1014, in _gcd_import
  File "<frozen importlib._bootstrap>", line 991, in _find_and_load
  File "<frozen importlib._bootstrap>", line 975, in _find_and_load_unlocked
  File "<frozen importlib._bootstrap>", line 671, in _load_unlocked
  File "<frozen importlib._bootstrap_external>", line 844, in exec_module
  File "<frozen importlib._bootstrap_external>", line 981, in get_code
  File "<frozen importlib._bootstrap_external>", line 911, in source_to_code
  File "<frozen importlib._bootstrap>", line 219, in _call_with_frames_removed
  File "/var/www/html/skytron_backend/Skytronsystem/skytron_api/urls.py", line 106
    ,
    ^
SyntaxError: invalid syntax
/var/www/html/skytron_backend/Skytronsystem/skytron_api/urls.py changed, reloading.
Watching for file changes with StatReloader
Performing system checks...

Exception in thread django-main-thread:
Traceback (most recent call last):
  File "/usr/lib/python3.8/threading.py", line 932, in _bootstrap_inner
    self.run()
  File "/usr/lib/python3.8/threading.py", line 870, in run
    self._target(*self._args, **self._kwargs)
  File "/usr/local/lib/python3.8/dist-packages/django/utils/autoreload.py", line 64, in wrapper
    fn(*args, **kwargs)
  File "/usr/local/lib/python3.8/dist-packages/django/core/management/commands/runserver.py", line 133, in inner_run
    self.check(display_num_errors=True)
  File "/usr/local/lib/python3.8/dist-packages/django/core/management/base.py", line 485, in check
    all_issues = checks.run_checks(
  File "/usr/local/lib/python3.8/dist-packages/django/core/checks/registry.py", line 88, in run_checks
    new_errors = check(app_configs=app_configs, databases=databases)
  File "/usr/local/lib/python3.8/dist-packages/django/core/checks/urls.py", line 14, in check_url_config
    return check_resolver(resolver)
  File "/usr/local/lib/python3.8/dist-packages/django/core/checks/urls.py", line 24, in check_resolver
    return check_method()
  File "/usr/local/lib/python3.8/dist-packages/django/urls/resolvers.py", line 494, in check
    for pattern in self.url_patterns:
  File "/usr/local/lib/python3.8/dist-packages/django/utils/functional.py", line 57, in __get__
    res = instance.__dict__[self.name] = self.func(instance)
  File "/usr/local/lib/python3.8/dist-packages/django/urls/resolvers.py", line 715, in url_patterns
    patterns = getattr(self.urlconf_module, "urlpatterns", self.urlconf_module)
  File "/usr/local/lib/python3.8/dist-packages/django/utils/functional.py", line 57, in __get__
    res = instance.__dict__[self.name] = self.func(instance)
  File "/usr/local/lib/python3.8/dist-packages/django/urls/resolvers.py", line 708, in urlconf_module
    return import_module(self.urlconf_name)
  File "/usr/lib/python3.8/importlib/__init__.py", line 127, in import_module
    return _bootstrap._gcd_import(name[level:], package, level)
  File "<frozen importlib._bootstrap>", line 1014, in _gcd_import
  File "<frozen importlib._bootstrap>", line 991, in _find_and_load
  File "<frozen importlib._bootstrap>", line 975, in _find_and_load_unlocked
  File "<frozen importlib._bootstrap>", line 671, in _load_unlocked
  File "<frozen importlib._bootstrap_external>", line 848, in exec_module
  File "<frozen importlib._bootstrap>", line 219, in _call_with_frames_removed
  File "/var/www/html/skytron_backend/Skytronsystem/Skytronsystem/urls.py", line 24, in <module>
    path('api/', include('skytron_api.urls')),  # Include the skytron_api URLs
  File "/usr/local/lib/python3.8/dist-packages/django/urls/conf.py", line 38, in include
    urlconf_module = import_module(urlconf_module)
  File "/usr/lib/python3.8/importlib/__init__.py", line 127, in import_module
    return _bootstrap._gcd_import(name[level:], package, level)
  File "<frozen importlib._bootstrap>", line 1014, in _gcd_import
  File "<frozen importlib._bootstrap>", line 991, in _find_and_load
  File "<frozen importlib._bootstrap>", line 975, in _find_and_load_unlocked
  File "<frozen importlib._bootstrap>", line 671, in _load_unlocked
  File "<frozen importlib._bootstrap_external>", line 848, in exec_module
  File "<frozen importlib._bootstrap>", line 219, in _call_with_frames_removed
  File "/var/www/html/skytron_backend/Skytronsystem/skytron_api/urls.py", line 11, in <module>
    from .views import (
ImportError: cannot import name 'SellFitDevice' from 'skytron_api.views' (/var/www/html/skytron_backend/Skytronsystem/skytron_api/views.py)
/var/www/html/skytron_backend/Skytronsystem/skytron_api/views.py changed, reloading.
Watching for file changes with StatReloader
Performing system checks...

System check identified no issues (0 silenced).
February 07, 2024 - 05:22:03
Django version 4.2.9, using settings 'Skytronsystem.settings'
Starting development server at http://0.0.0.0:2000/
Quit the server with CONTROL-C.

Not Found: /api/devicestock/SellListAvailableDeviceStock/
[07/Feb/2024 05:23:59] "POST /api/devicestock/SellListAvailableDeviceStock/ HTTP/1.1" 404 15703
Method Not Allowed: /api/sell/SellListAvailableDeviceStock/
[07/Feb/2024 05:24:30] "POST /api/sell/SellListAvailableDeviceStock/ HTTP/1.1" 405 41
Internal Server Error: /api/sell/SellListAvailableDeviceStock/
Traceback (most recent call last):
  File "/usr/local/lib/python3.8/dist-packages/django/core/handlers/exception.py", line 55, in inner
    response = get_response(request)
  File "/usr/local/lib/python3.8/dist-packages/django/core/handlers/base.py", line 197, in _get_response
    response = wrapped_callback(request, *callback_args, **callback_kwargs)
  File "/usr/local/lib/python3.8/dist-packages/django/views/decorators/csrf.py", line 56, in wrapper_view
    return view_func(*args, **kwargs)
  File "/usr/local/lib/python3.8/dist-packages/django/views/generic/base.py", line 104, in view
    return self.dispatch(request, *args, **kwargs)
  File "/usr/local/lib/python3.8/dist-packages/rest_framework/views.py", line 509, in dispatch
    response = self.handle_exception(exc)
  File "/usr/local/lib/python3.8/dist-packages/rest_framework/views.py", line 469, in handle_exception
    self.raise_uncaught_exception(exc)
  File "/usr/local/lib/python3.8/dist-packages/rest_framework/views.py", line 480, in raise_uncaught_exception
    raise exc
  File "/usr/local/lib/python3.8/dist-packages/rest_framework/views.py", line 506, in dispatch
    response = handler(request, *args, **kwargs)
  File "/usr/local/lib/python3.8/dist-packages/rest_framework/decorators.py", line 50, in handler
    return func(*args, **kwargs)
  File "/var/www/html/skytron_backend/Skytronsystem/skytron_api/views.py", line 94, in SellListAvailableDeviceStock
    device_stock = StockAssignment.objects.filter(stockassignment__stock_status='Available_for_fitting')
  File "/usr/local/lib/python3.8/dist-packages/django/db/models/manager.py", line 87, in manager_method
    return getattr(self.get_queryset(), name)(*args, **kwargs)
  File "/usr/local/lib/python3.8/dist-packages/django/db/models/query.py", line 1436, in filter
    return self._filter_or_exclude(False, args, kwargs)
  File "/usr/local/lib/python3.8/dist-packages/django/db/models/query.py", line 1454, in _filter_or_exclude
    clone._filter_or_exclude_inplace(negate, args, kwargs)
  File "/usr/local/lib/python3.8/dist-packages/django/db/models/query.py", line 1461, in _filter_or_exclude_inplace
    self._query.add_q(Q(*args, **kwargs))
  File "/usr/local/lib/python3.8/dist-packages/django/db/models/sql/query.py", line 1546, in add_q
    clause, _ = self._add_q(q_object, self.used_aliases)
  File "/usr/local/lib/python3.8/dist-packages/django/db/models/sql/query.py", line 1577, in _add_q
    child_clause, needed_inner = self.build_filter(
  File "/usr/local/lib/python3.8/dist-packages/django/db/models/sql/query.py", line 1427, in build_filter
    lookups, parts, reffed_expression = self.solve_lookup_type(arg, summarize)
  File "/usr/local/lib/python3.8/dist-packages/django/db/models/sql/query.py", line 1237, in solve_lookup_type
    _, field, _, lookup_parts = self.names_to_path(lookup_splitted, self.get_meta())
  File "/usr/local/lib/python3.8/dist-packages/django/db/models/sql/query.py", line 1725, in names_to_path
    raise FieldError(
django.core.exceptions.FieldError: Cannot resolve keyword 'stockassignment' into field. Choices are: assigned, assigned_by, assigned_by_id, dealer, dealer_id, device, device_id, id, shipping_remark, stock_status
[07/Feb/2024 05:24:40] "GET /api/sell/SellListAvailableDeviceStock/ HTTP/1.1" 500 137218
/var/www/html/skytron_backend/Skytronsystem/skytron_api/views.py changed, reloading.
Watching for file changes with StatReloader
Performing system checks...

System check identified no issues (0 silenced).
February 07, 2024 - 05:26:10
Django version 4.2.9, using settings 'Skytronsystem.settings'
Starting development server at http://0.0.0.0:2000/
Quit the server with CONTROL-C.

[07/Feb/2024 05:26:14] "GET /api/sell/SellListAvailableDeviceStock/ HTTP/1.1" 200 580
[07/Feb/2024 05:27:39] "GET /api/sell/SellListAvailableDeviceStock/ HTTP/1.1" 200 580
/var/www/html/skytron_backend/Skytronsystem/skytron_api/views.py changed, reloading.
Watching for file changes with StatReloader
Performing system checks...

System check identified no issues (0 silenced).
February 07, 2024 - 05:29:24
Django version 4.2.9, using settings 'Skytronsystem.settings'
Starting development server at http://0.0.0.0:2000/
Quit the server with CONTROL-C.

/var/www/html/skytron_backend/Skytronsystem/skytron_api/views.py changed, reloading.
Watching for file changes with StatReloader
Performing system checks...

System check identified no issues (0 silenced).
February 07, 2024 - 05:29:47
Django version 4.2.9, using settings 'Skytronsystem.settings'
Starting development server at http://0.0.0.0:2000/
Quit the server with CONTROL-C.

Method Not Allowed: /api/sell/SellFitDevice/
[07/Feb/2024 05:30:35] "GET /api/sell/SellFitDevice/ HTTP/1.1" 405 40
Method Not Allowed: /api/sell/SellFitDevice/
[07/Feb/2024 05:30:41] "POST /api/sell/SellFitDevice/ HTTP/1.1" 405 41
Internal Server Error: /api/sell/SellFitDevice/
Traceback (most recent call last):
  File "/usr/local/lib/python3.8/dist-packages/django/core/handlers/exception.py", line 55, in inner
    response = get_response(request)
  File "/usr/local/lib/python3.8/dist-packages/django/core/handlers/base.py", line 197, in _get_response
    response = wrapped_callback(request, *callback_args, **callback_kwargs)
  File "/usr/local/lib/python3.8/dist-packages/django/views/decorators/csrf.py", line 56, in wrapper_view
    return view_func(*args, **kwargs)
  File "/usr/local/lib/python3.8/dist-packages/django/views/generic/base.py", line 104, in view
    return self.dispatch(request, *args, **kwargs)
  File "/usr/local/lib/python3.8/dist-packages/rest_framework/views.py", line 509, in dispatch
    response = self.handle_exception(exc)
  File "/usr/local/lib/python3.8/dist-packages/rest_framework/views.py", line 469, in handle_exception
    self.raise_uncaught_exception(exc)
  File "/usr/local/lib/python3.8/dist-packages/rest_framework/views.py", line 480, in raise_uncaught_exception
    raise exc
  File "/usr/local/lib/python3.8/dist-packages/rest_framework/views.py", line 506, in dispatch
    response = handler(request, *args, **kwargs)
  File "/usr/local/lib/python3.8/dist-packages/rest_framework/decorators.py", line 50, in handler
    return func(*args, **kwargs)
  File "/var/www/html/skytron_backend/Skytronsystem/skytron_api/views.py", line 102, in SellFitDevice
    device_id=int(request.data['device_id'])
KeyError: 'device_id'
[07/Feb/2024 05:31:16] "PATCH /api/sell/SellFitDevice/ HTTP/1.1" 500 91852
Internal Server Error: /api/sell/SellFitDevice/
Traceback (most recent call last):
  File "/usr/local/lib/python3.8/dist-packages/django/core/handlers/exception.py", line 55, in inner
    response = get_response(request)
  File "/usr/local/lib/python3.8/dist-packages/django/core/handlers/base.py", line 197, in _get_response
    response = wrapped_callback(request, *callback_args, **callback_kwargs)
  File "/usr/local/lib/python3.8/dist-packages/django/views/decorators/csrf.py", line 56, in wrapper_view
    return view_func(*args, **kwargs)
  File "/usr/local/lib/python3.8/dist-packages/django/views/generic/base.py", line 104, in view
    return self.dispatch(request, *args, **kwargs)
  File "/usr/local/lib/python3.8/dist-packages/rest_framework/views.py", line 509, in dispatch
    response = self.handle_exception(exc)
  File "/usr/local/lib/python3.8/dist-packages/rest_framework/views.py", line 469, in handle_exception
    self.raise_uncaught_exception(exc)
  File "/usr/local/lib/python3.8/dist-packages/rest_framework/views.py", line 480, in raise_uncaught_exception
    raise exc
  File "/usr/local/lib/python3.8/dist-packages/rest_framework/views.py", line 506, in dispatch
    response = handler(request, *args, **kwargs)
  File "/usr/local/lib/python3.8/dist-packages/rest_framework/decorators.py", line 50, in handler
    return func(*args, **kwargs)
  File "/var/www/html/skytron_backend/Skytronsystem/skytron_api/views.py", line 103, in SellFitDevice
    stock_assignment = get_object_or_404(StockAssignment, device=device_id, device_stock='Available_for_fitting')
  File "/usr/local/lib/python3.8/dist-packages/django/shortcuts.py", line 85, in get_object_or_404
    return queryset.get(*args, **kwargs)
  File "/usr/local/lib/python3.8/dist-packages/django/db/models/query.py", line 623, in get
    clone = self._chain() if self.query.combinator else self.filter(*args, **kwargs)
  File "/usr/local/lib/python3.8/dist-packages/django/db/models/query.py", line 1436, in filter
    return self._filter_or_exclude(False, args, kwargs)
  File "/usr/local/lib/python3.8/dist-packages/django/db/models/query.py", line 1454, in _filter_or_exclude
    clone._filter_or_exclude_inplace(negate, args, kwargs)
  File "/usr/local/lib/python3.8/dist-packages/django/db/models/query.py", line 1461, in _filter_or_exclude_inplace
    self._query.add_q(Q(*args, **kwargs))
  File "/usr/local/lib/python3.8/dist-packages/django/db/models/sql/query.py", line 1546, in add_q
    clause, _ = self._add_q(q_object, self.used_aliases)
  File "/usr/local/lib/python3.8/dist-packages/django/db/models/sql/query.py", line 1577, in _add_q
    child_clause, needed_inner = self.build_filter(
  File "/usr/local/lib/python3.8/dist-packages/django/db/models/sql/query.py", line 1427, in build_filter
    lookups, parts, reffed_expression = self.solve_lookup_type(arg, summarize)
  File "/usr/local/lib/python3.8/dist-packages/django/db/models/sql/query.py", line 1237, in solve_lookup_type
    _, field, _, lookup_parts = self.names_to_path(lookup_splitted, self.get_meta())
  File "/usr/local/lib/python3.8/dist-packages/django/db/models/sql/query.py", line 1725, in names_to_path
    raise FieldError(
django.core.exceptions.FieldError: Cannot resolve keyword 'device_stock' into field. Choices are: assigned, assigned_by, assigned_by_id, dealer, dealer_id, device, device_id, id, shipping_remark, stock_status
[07/Feb/2024 05:32:04] "PATCH /api/sell/SellFitDevice/ HTTP/1.1" 500 142620
/var/www/html/skytron_backend/Skytronsystem/skytron_api/views.py changed, reloading.
Watching for file changes with StatReloader
Performing system checks...

System check identified no issues (0 silenced).
February 07, 2024 - 05:33:15
Django version 4.2.9, using settings 'Skytronsystem.settings'
Starting development server at http://0.0.0.0:2000/
Quit the server with CONTROL-C.

[07/Feb/2024 05:33:18] "PATCH /api/sell/SellFitDevice/ HTTP/1.1" 200 241
[07/Feb/2024 05:33:30] "PATCH /api/sell/SellFitDevice/ HTTP/1.1" 200 241
[07/Feb/2024 05:34:41] "PATCH /api/sell/SellFitDevice/ HTTP/1.1" 200 241
/var/www/html/skytron_backend/Skytronsystem/skytron_api/views.py changed, reloading.
Watching for file changes with StatReloader
Performing system checks...

System check identified no issues (0 silenced).
February 07, 2024 - 05:35:20
Django version 4.2.9, using settings 'Skytronsystem.settings'
Starting development server at http://0.0.0.0:2000/
Quit the server with CONTROL-C.

[07/Feb/2024 05:35:23] "PATCH /api/sell/SellFitDevice/ HTTP/1.1" 200 226
Not Found: /api/sell/SellFitDevice/
[07/Feb/2024 05:35:27] "PATCH /api/sell/SellFitDevice/ HTTP/1.1" 404 23
/var/www/html/skytron_backend/Skytronsystem/skytron_api/views.py changed, reloading.
Watching for file changes with StatReloader
Performing system checks...

System check identified no issues (0 silenced).
February 07, 2024 - 05:43:22
Django version 4.2.9, using settings 'Skytronsystem.settings'
Starting development server at http://0.0.0.0:2000/
Quit the server with CONTROL-C.

/var/www/html/skytron_backend/Skytronsystem/skytron_api/urls.py changed, reloading.
Watching for file changes with StatReloader
Performing system checks...

System check identified no issues (0 silenced).
February 07, 2024 - 05:58:41
Django version 4.2.9, using settings 'Skytronsystem.settings'
Starting development server at http://0.0.0.0:2000/
Quit the server with CONTROL-C.

Method Not Allowed: /api/sell/SellListAvailableDeviceStock/
[07/Feb/2024 06:01:44] "PATCH /api/sell/SellListAvailableDeviceStock/ HTTP/1.1" 405 42
/var/www/html/skytron_backend/Skytronsystem/skytron_api/views.py changed, reloading.
Watching for file changes with StatReloader
Performing system checks...

System check identified no issues (0 silenced).
February 07, 2024 - 06:02:06
Django version 4.2.9, using settings 'Skytronsystem.settings'
Starting development server at http://0.0.0.0:2000/
Quit the server with CONTROL-C.

[07/Feb/2024 06:03:00] "PATCH /api/sell/activate_esim_request/ HTTP/1.1" 200 250
Not Found: /api/sell/activate_esim_request/
[07/Feb/2024 06:03:58] "PATCH /api/sell/activate_esim_request/ HTTP/1.1" 404 23
/var/www/html/skytron_backend/Skytronsystem/skytron_api/views.py changed, reloading.
Watching for file changes with StatReloader
Performing system checks...

System check identified no issues (0 silenced).
February 07, 2024 - 06:06:55
Django version 4.2.9, using settings 'Skytronsystem.settings'
Starting development server at http://0.0.0.0:2000/
Quit the server with CONTROL-C.

/var/www/html/skytron_backend/Skytronsystem/skytron_api/views.py changed, reloading.
Watching for file changes with StatReloader
Performing system checks...

System check identified no issues (0 silenced).
February 07, 2024 - 06:06:58
Django version 4.2.9, using settings 'Skytronsystem.settings'
Starting development server at http://0.0.0.0:2000/
Quit the server with CONTROL-C.

[07/Feb/2024 06:07:39] "PATCH /api/sell/confirm_esim_activation/ HTTP/1.1" 200 248
Not Found: /api/sell/confirm_esim_activation/
[07/Feb/2024 06:08:26] "PATCH /api/sell/confirm_esim_activation/ HTTP/1.1" 404 23
[07/Feb/2024 06:11:10] "PATCH /api/sell/configure_ip_port/ HTTP/1.1" 200 242
Not Found: /api/sell/configure_ip_port/
[07/Feb/2024 06:12:05] "PATCH /api/sell/configure_ip_port/ HTTP/1.1" 404 23
[07/Feb/2024 06:14:46] "PATCH /api/sell/configure_sos_gateway/ HTTP/1.1" 200 253
Not Found: /api/sell/configure_sos_gateway/
[07/Feb/2024 06:18:35] "PATCH /api/sell/configure_sos_gateway/ HTTP/1.1" 404 23
[07/Feb/2024 06:19:43] "PATCH /api/sell/configure_sms_gateway/ HTTP/1.1" 200 253
Not Found: /api/sell/configure_sms_gateway/
[07/Feb/2024 06:20:06] "PATCH /api/sell/configure_sms_gateway/ HTTP/1.1" 404 23
[07/Feb/2024 06:20:53] "PATCH /api/sell/mark_device_defective/ HTTP/1.1" 200 248
Not Found: /api/sell/mark_device_defective/
[07/Feb/2024 06:21:12] "PATCH /api/sell/mark_device_defective/ HTTP/1.1" 404 23
[07/Feb/2024 06:21:59] "PATCH /api/sell/return_to_manufacturer/ HTTP/1.1" 200 261
Not Found: /api/sell/return_to_manufacturer/
[07/Feb/2024 06:22:26] "PATCH /api/sell/return_to_manufacturer/ HTTP/1.1" 404 23
/var/www/html/skytron_backend/Skytronsystem/skytron_api/serializers.py changed, reloading.
Watching for file changes with StatReloader
Performing system checks...

System check identified no issues (0 silenced).
February 07, 2024 - 06:34:50
Django version 4.2.9, using settings 'Skytronsystem.settings'
Starting development server at http://0.0.0.0:2000/
Quit the server with CONTROL-C.

/var/www/html/skytron_backend/Skytronsystem/skytron_api/views.py changed, reloading.
Watching for file changes with StatReloader
Performing system checks...

System check identified no issues (0 silenced).
February 07, 2024 - 06:35:05
Django version 4.2.9, using settings 'Skytronsystem.settings'
Starting development server at http://0.0.0.0:2000/
Quit the server with CONTROL-C.

/var/www/html/skytron_backend/Skytronsystem/skytron_api/serializers.py changed, reloading.
Watching for file changes with StatReloader
Performing system checks...

System check identified no issues (0 silenced).
February 07, 2024 - 06:35:31
Django version 4.2.9, using settings 'Skytronsystem.settings'
Starting development server at http://0.0.0.0:2000/
Quit the server with CONTROL-C.

/var/www/html/skytron_backend/Skytronsystem/skytron_api/views.py changed, reloading.
Watching for file changes with StatReloader
Performing system checks...

System check identified no issues (0 silenced).
February 07, 2024 - 06:35:58
Django version 4.2.9, using settings 'Skytronsystem.settings'
Starting development server at http://0.0.0.0:2000/
Quit the server with CONTROL-C.

/var/www/html/skytron_backend/Skytronsystem/skytron_api/views.py changed, reloading.
Watching for file changes with StatReloader
Performing system checks...

System check identified no issues (0 silenced).
February 07, 2024 - 06:36:54
Django version 4.2.9, using settings 'Skytronsystem.settings'
Starting development server at http://0.0.0.0:2000/
Quit the server with CONTROL-C.

/var/www/html/skytron_backend/Skytronsystem/skytron_api/urls.py changed, reloading.
Watching for file changes with StatReloader
Performing system checks...

System check identified no issues (0 silenced).
February 07, 2024 - 06:37:38
Django version 4.2.9, using settings 'Skytronsystem.settings'
Starting development server at http://0.0.0.0:2000/
Quit the server with CONTROL-C.

/var/www/html/skytron_backend/Skytronsystem/skytron_api/models.py changed, reloading.
Watching for file changes with StatReloader
Performing system checks...

System check identified no issues (0 silenced).
February 07, 2024 - 06:38:08
Django version 4.2.9, using settings 'Skytronsystem.settings'
Starting development server at http://0.0.0.0:2000/
Quit the server with CONTROL-C.

/var/www/html/skytron_backend/Skytronsystem/skytron_api/views.py changed, reloading.
Watching for file changes with StatReloader
Performing system checks...

Exception in thread django-main-thread:
Traceback (most recent call last):
  File "/usr/lib/python3.8/threading.py", line 932, in _bootstrap_inner
    self.run()
  File "/usr/lib/python3.8/threading.py", line 870, in run
    self._target(*self._args, **self._kwargs)
  File "/usr/local/lib/python3.8/dist-packages/django/utils/autoreload.py", line 64, in wrapper
    fn(*args, **kwargs)
  File "/usr/local/lib/python3.8/dist-packages/django/core/management/commands/runserver.py", line 133, in inner_run
    self.check(display_num_errors=True)
  File "/usr/local/lib/python3.8/dist-packages/django/core/management/base.py", line 485, in check
    all_issues = checks.run_checks(
  File "/usr/local/lib/python3.8/dist-packages/django/core/checks/registry.py", line 88, in run_checks
    new_errors = check(app_configs=app_configs, databases=databases)
  File "/usr/local/lib/python3.8/dist-packages/django/core/checks/urls.py", line 14, in check_url_config
    return check_resolver(resolver)
  File "/usr/local/lib/python3.8/dist-packages/django/core/checks/urls.py", line 24, in check_resolver
    return check_method()
  File "/usr/local/lib/python3.8/dist-packages/django/urls/resolvers.py", line 494, in check
    for pattern in self.url_patterns:
  File "/usr/local/lib/python3.8/dist-packages/django/utils/functional.py", line 57, in __get__
    res = instance.__dict__[self.name] = self.func(instance)
  File "/usr/local/lib/python3.8/dist-packages/django/urls/resolvers.py", line 715, in url_patterns
    patterns = getattr(self.urlconf_module, "urlpatterns", self.urlconf_module)
  File "/usr/local/lib/python3.8/dist-packages/django/utils/functional.py", line 57, in __get__
    res = instance.__dict__[self.name] = self.func(instance)
  File "/usr/local/lib/python3.8/dist-packages/django/urls/resolvers.py", line 708, in urlconf_module
    return import_module(self.urlconf_name)
  File "/usr/lib/python3.8/importlib/__init__.py", line 127, in import_module
    return _bootstrap._gcd_import(name[level:], package, level)
  File "<frozen importlib._bootstrap>", line 1014, in _gcd_import
  File "<frozen importlib._bootstrap>", line 991, in _find_and_load
  File "<frozen importlib._bootstrap>", line 975, in _find_and_load_unlocked
  File "<frozen importlib._bootstrap>", line 671, in _load_unlocked
  File "<frozen importlib._bootstrap_external>", line 848, in exec_module
  File "<frozen importlib._bootstrap>", line 219, in _call_with_frames_removed
  File "/var/www/html/skytron_backend/Skytronsystem/Skytronsystem/urls.py", line 24, in <module>
    path('api/', include('skytron_api.urls')),  # Include the skytron_api URLs
  File "/usr/local/lib/python3.8/dist-packages/django/urls/conf.py", line 38, in include
    urlconf_module = import_module(urlconf_module)
  File "/usr/lib/python3.8/importlib/__init__.py", line 127, in import_module
    return _bootstrap._gcd_import(name[level:], package, level)
  File "<frozen importlib._bootstrap>", line 1014, in _gcd_import
  File "<frozen importlib._bootstrap>", line 991, in _find_and_load
  File "<frozen importlib._bootstrap>", line 975, in _find_and_load_unlocked
  File "<frozen importlib._bootstrap>", line 671, in _load_unlocked
  File "<frozen importlib._bootstrap_external>", line 848, in exec_module
  File "<frozen importlib._bootstrap>", line 219, in _call_with_frames_removed
  File "/var/www/html/skytron_backend/Skytronsystem/skytron_api/urls.py", line 2, in <module>
    from .views import create_user, update_user, password_reset, send_email_otp, send_sms_otp, user_login, user_logout, user_get_parent, get_list, get_details, validate_otp
  File "/var/www/html/skytron_backend/Skytronsystem/skytron_api/views.py", line 114
    status='Dealer_OTP_Sent',
    ^
SyntaxError: invalid syntax
/var/www/html/skytron_backend/Skytronsystem/skytron_api/views.py changed, reloading.
Watching for file changes with StatReloader
Performing system checks...

Exception in thread django-main-thread:
Traceback (most recent call last):
  File "/usr/lib/python3.8/threading.py", line 932, in _bootstrap_inner
    self.run()
  File "/usr/lib/python3.8/threading.py", line 870, in run
    self._target(*self._args, **self._kwargs)
  File "/usr/local/lib/python3.8/dist-packages/django/utils/autoreload.py", line 64, in wrapper
    fn(*args, **kwargs)
  File "/usr/local/lib/python3.8/dist-packages/django/core/management/commands/runserver.py", line 133, in inner_run
    self.check(display_num_errors=True)
  File "/usr/local/lib/python3.8/dist-packages/django/core/management/base.py", line 485, in check
    all_issues = checks.run_checks(
  File "/usr/local/lib/python3.8/dist-packages/django/core/checks/registry.py", line 88, in run_checks
    new_errors = check(app_configs=app_configs, databases=databases)
  File "/usr/local/lib/python3.8/dist-packages/django/core/checks/urls.py", line 14, in check_url_config
    return check_resolver(resolver)
  File "/usr/local/lib/python3.8/dist-packages/django/core/checks/urls.py", line 24, in check_resolver
    return check_method()
  File "/usr/local/lib/python3.8/dist-packages/django/urls/resolvers.py", line 494, in check
    for pattern in self.url_patterns:
  File "/usr/local/lib/python3.8/dist-packages/django/utils/functional.py", line 57, in __get__
    res = instance.__dict__[self.name] = self.func(instance)
  File "/usr/local/lib/python3.8/dist-packages/django/urls/resolvers.py", line 715, in url_patterns
    patterns = getattr(self.urlconf_module, "urlpatterns", self.urlconf_module)
  File "/usr/local/lib/python3.8/dist-packages/django/utils/functional.py", line 57, in __get__
    res = instance.__dict__[self.name] = self.func(instance)
  File "/usr/local/lib/python3.8/dist-packages/django/urls/resolvers.py", line 708, in urlconf_module
    return import_module(self.urlconf_name)
  File "/usr/lib/python3.8/importlib/__init__.py", line 127, in import_module
    return _bootstrap._gcd_import(name[level:], package, level)
  File "<frozen importlib._bootstrap>", line 1014, in _gcd_import
  File "<frozen importlib._bootstrap>", line 991, in _find_and_load
  File "<frozen importlib._bootstrap>", line 975, in _find_and_load_unlocked
  File "<frozen importlib._bootstrap>", line 671, in _load_unlocked
  File "<frozen importlib._bootstrap_external>", line 848, in exec_module
  File "<frozen importlib._bootstrap>", line 219, in _call_with_frames_removed
  File "/var/www/html/skytron_backend/Skytronsystem/Skytronsystem/urls.py", line 24, in <module>
    path('api/', include('skytron_api.urls')),  # Include the skytron_api URLs
  File "/usr/local/lib/python3.8/dist-packages/django/urls/conf.py", line 38, in include
    urlconf_module = import_module(urlconf_module)
  File "/usr/lib/python3.8/importlib/__init__.py", line 127, in import_module
    return _bootstrap._gcd_import(name[level:], package, level)
  File "<frozen importlib._bootstrap>", line 1014, in _gcd_import
  File "<frozen importlib._bootstrap>", line 991, in _find_and_load
  File "<frozen importlib._bootstrap>", line 975, in _find_and_load_unlocked
  File "<frozen importlib._bootstrap>", line 671, in _load_unlocked
  File "<frozen importlib._bootstrap_external>", line 848, in exec_module
  File "<frozen importlib._bootstrap>", line 219, in _call_with_frames_removed
  File "/var/www/html/skytron_backend/Skytronsystem/skytron_api/urls.py", line 2, in <module>
    from .views import create_user, update_user, password_reset, send_email_otp, send_sms_otp, user_login, user_logout, user_get_parent, get_list, get_details, validate_otp
  File "/var/www/html/skytron_backend/Skytronsystem/skytron_api/views.py", line 114
    status='Dealer_OTP_Sent',
    ^
SyntaxError: invalid syntax
/var/www/html/skytron_backend/Skytronsystem/skytron_api/views.py changed, reloading.
Watching for file changes with StatReloader
Performing system checks...

Exception in thread django-main-thread:
Traceback (most recent call last):
  File "/usr/lib/python3.8/threading.py", line 932, in _bootstrap_inner
    self.run()
  File "/usr/lib/python3.8/threading.py", line 870, in run
    self._target(*self._args, **self._kwargs)
  File "/usr/local/lib/python3.8/dist-packages/django/utils/autoreload.py", line 64, in wrapper
    fn(*args, **kwargs)
  File "/usr/local/lib/python3.8/dist-packages/django/core/management/commands/runserver.py", line 133, in inner_run
    self.check(display_num_errors=True)
  File "/usr/local/lib/python3.8/dist-packages/django/core/management/base.py", line 485, in check
    all_issues = checks.run_checks(
  File "/usr/local/lib/python3.8/dist-packages/django/core/checks/registry.py", line 88, in run_checks
    new_errors = check(app_configs=app_configs, databases=databases)
  File "/usr/local/lib/python3.8/dist-packages/django/core/checks/urls.py", line 14, in check_url_config
    return check_resolver(resolver)
  File "/usr/local/lib/python3.8/dist-packages/django/core/checks/urls.py", line 24, in check_resolver
    return check_method()
  File "/usr/local/lib/python3.8/dist-packages/django/urls/resolvers.py", line 494, in check
    for pattern in self.url_patterns:
  File "/usr/local/lib/python3.8/dist-packages/django/utils/functional.py", line 57, in __get__
    res = instance.__dict__[self.name] = self.func(instance)
  File "/usr/local/lib/python3.8/dist-packages/django/urls/resolvers.py", line 715, in url_patterns
    patterns = getattr(self.urlconf_module, "urlpatterns", self.urlconf_module)
  File "/usr/local/lib/python3.8/dist-packages/django/utils/functional.py", line 57, in __get__
    res = instance.__dict__[self.name] = self.func(instance)
  File "/usr/local/lib/python3.8/dist-packages/django/urls/resolvers.py", line 708, in urlconf_module
    return import_module(self.urlconf_name)
  File "/usr/lib/python3.8/importlib/__init__.py", line 127, in import_module
    return _bootstrap._gcd_import(name[level:], package, level)
  File "<frozen importlib._bootstrap>", line 1014, in _gcd_import
  File "<frozen importlib._bootstrap>", line 991, in _find_and_load
  File "<frozen importlib._bootstrap>", line 975, in _find_and_load_unlocked
  File "<frozen importlib._bootstrap>", line 671, in _load_unlocked
  File "<frozen importlib._bootstrap_external>", line 848, in exec_module
  File "<frozen importlib._bootstrap>", line 219, in _call_with_frames_removed
  File "/var/www/html/skytron_backend/Skytronsystem/Skytronsystem/urls.py", line 24, in <module>
    path('api/', include('skytron_api.urls')),  # Include the skytron_api URLs
  File "/usr/local/lib/python3.8/dist-packages/django/urls/conf.py", line 38, in include
    urlconf_module = import_module(urlconf_module)
  File "/usr/lib/python3.8/importlib/__init__.py", line 127, in import_module
    return _bootstrap._gcd_import(name[level:], package, level)
  File "<frozen importlib._bootstrap>", line 1014, in _gcd_import
  File "<frozen importlib._bootstrap>", line 991, in _find_and_load
  File "<frozen importlib._bootstrap>", line 975, in _find_and_load_unlocked
  File "<frozen importlib._bootstrap>", line 671, in _load_unlocked
  File "<frozen importlib._bootstrap_external>", line 848, in exec_module
  File "<frozen importlib._bootstrap>", line 219, in _call_with_frames_removed
  File "/var/www/html/skytron_backend/Skytronsystem/skytron_api/urls.py", line 2, in <module>
    from .views import create_user, update_user, password_reset, send_email_otp, send_sms_otp, user_login, user_logout, user_get_parent, get_list, get_details, validate_otp
  File "/var/www/html/skytron_backend/Skytronsystem/skytron_api/views.py", line 114
    status='Dealer_OTP_Sent',
    ^
SyntaxError: invalid syntax
/var/www/html/skytron_backend/Skytronsystem/skytron_api/views.py changed, reloading.
Watching for file changes with StatReloader
Performing system checks...

System check identified no issues (0 silenced).
February 07, 2024 - 06:59:16
Django version 4.2.9, using settings 'Skytronsystem.settings'
Starting development server at http://0.0.0.0:2000/
Quit the server with CONTROL-C.

/var/www/html/skytron_backend/Skytronsystem/skytron_api/views.py changed, reloading.
Watching for file changes with StatReloader
Performing system checks...

System check identified no issues (0 silenced).
February 07, 2024 - 06:59:19
Django version 4.2.9, using settings 'Skytronsystem.settings'
Starting development server at http://0.0.0.0:2000/
Quit the server with CONTROL-C.

Internal Server Error: /api/tag/TagDevice2Vehicle/
Traceback (most recent call last):
  File "/usr/local/lib/python3.8/dist-packages/django/utils/datastructures.py", line 84, in __getitem__
    list_ = super().__getitem__(key)
KeyError: 'vehicle_reg_no'

During handling of the above exception, another exception occurred:

Traceback (most recent call last):
  File "/usr/local/lib/python3.8/dist-packages/django/core/handlers/exception.py", line 55, in inner
    response = get_response(request)
  File "/usr/local/lib/python3.8/dist-packages/django/core/handlers/base.py", line 197, in _get_response
    response = wrapped_callback(request, *callback_args, **callback_kwargs)
  File "/usr/local/lib/python3.8/dist-packages/django/views/decorators/csrf.py", line 56, in wrapper_view
    return view_func(*args, **kwargs)
  File "/usr/local/lib/python3.8/dist-packages/django/views/generic/base.py", line 104, in view
    return self.dispatch(request, *args, **kwargs)
  File "/usr/local/lib/python3.8/dist-packages/rest_framework/views.py", line 509, in dispatch
    response = self.handle_exception(exc)
  File "/usr/local/lib/python3.8/dist-packages/rest_framework/views.py", line 469, in handle_exception
    self.raise_uncaught_exception(exc)
  File "/usr/local/lib/python3.8/dist-packages/rest_framework/views.py", line 480, in raise_uncaught_exception
    raise exc
  File "/usr/local/lib/python3.8/dist-packages/rest_framework/views.py", line 506, in dispatch
    response = handler(request, *args, **kwargs)
  File "/usr/local/lib/python3.8/dist-packages/rest_framework/decorators.py", line 50, in handler
    return func(*args, **kwargs)
  File "/var/www/html/skytron_backend/Skytronsystem/skytron_api/views.py", line 107, in TagDevice2Vehicle
    vehicle_reg_no=request.data['vehicle_reg_no'],
  File "/usr/local/lib/python3.8/dist-packages/django/utils/datastructures.py", line 86, in __getitem__
    raise MultiValueDictKeyError(key)
django.utils.datastructures.MultiValueDictKeyError: 'vehicle_reg_no'
[07/Feb/2024 06:59:36] "POST /api/tag/TagDevice2Vehicle/ HTTP/1.1" 500 108915
/var/www/html/skytron_backend/Skytronsystem/skytron_api/views.py changed, reloading.
Watching for file changes with StatReloader
Performing system checks...

System check identified no issues (0 silenced).
February 07, 2024 - 07:04:40
Django version 4.2.9, using settings 'Skytronsystem.settings'
Starting development server at http://0.0.0.0:2000/
Quit the server with CONTROL-C.

Internal Server Error: /api/tag/TagDevice2Vehicle/
Traceback (most recent call last):
  File "/usr/local/lib/python3.8/dist-packages/django/utils/datastructures.py", line 84, in __getitem__
    list_ = super().__getitem__(key)
KeyError: 'vehicle_owner'

During handling of the above exception, another exception occurred:

Traceback (most recent call last):
  File "/usr/local/lib/python3.8/dist-packages/django/core/handlers/exception.py", line 55, in inner
    response = get_response(request)
  File "/usr/local/lib/python3.8/dist-packages/django/core/handlers/base.py", line 197, in _get_response
    response = wrapped_callback(request, *callback_args, **callback_kwargs)
  File "/usr/local/lib/python3.8/dist-packages/django/views/decorators/csrf.py", line 56, in wrapper_view
    return view_func(*args, **kwargs)
  File "/usr/local/lib/python3.8/dist-packages/django/views/generic/base.py", line 104, in view
    return self.dispatch(request, *args, **kwargs)
  File "/usr/local/lib/python3.8/dist-packages/rest_framework/views.py", line 509, in dispatch
    response = self.handle_exception(exc)
  File "/usr/local/lib/python3.8/dist-packages/rest_framework/views.py", line 469, in handle_exception
    self.raise_uncaught_exception(exc)
  File "/usr/local/lib/python3.8/dist-packages/rest_framework/views.py", line 480, in raise_uncaught_exception
    raise exc
  File "/usr/local/lib/python3.8/dist-packages/rest_framework/views.py", line 506, in dispatch
    response = handler(request, *args, **kwargs)
  File "/usr/local/lib/python3.8/dist-packages/rest_framework/decorators.py", line 50, in handler
    return func(*args, **kwargs)
  File "/var/www/html/skytron_backend/Skytronsystem/skytron_api/views.py", line 106, in TagDevice2Vehicle
    vehicle_owner_id=request.data['vehicle_owner'],
  File "/usr/local/lib/python3.8/dist-packages/django/utils/datastructures.py", line 86, in __getitem__
    raise MultiValueDictKeyError(key)
django.utils.datastructures.MultiValueDictKeyError: 'vehicle_owner'
[07/Feb/2024 07:04:50] "POST /api/tag/TagDevice2Vehicle/ HTTP/1.1" 500 109037
/var/www/html/skytron_backend/Skytronsystem/skytron_api/views.py changed, reloading.
Watching for file changes with StatReloader
Performing system checks...

System check identified no issues (0 silenced).
February 07, 2024 - 07:06:01
Django version 4.2.9, using settings 'Skytronsystem.settings'
Starting development server at http://0.0.0.0:2000/
Quit the server with CONTROL-C.

/var/www/html/skytron_backend/Skytronsystem/skytron_api/views.py changed, reloading.
Watching for file changes with StatReloader
Performing system checks...

System check identified no issues (0 silenced).
February 07, 2024 - 07:06:07
Django version 4.2.9, using settings 'Skytronsystem.settings'
Starting development server at http://0.0.0.0:2000/
Quit the server with CONTROL-C.

Internal Server Error: /api/tag/TagDevice2Vehicle/
Traceback (most recent call last):
  File "/usr/local/lib/python3.8/dist-packages/django/utils/datastructures.py", line 84, in __getitem__
    list_ = super().__getitem__(key)
KeyError: 'vehicle_owner'

During handling of the above exception, another exception occurred:

Traceback (most recent call last):
  File "/usr/local/lib/python3.8/dist-packages/django/core/handlers/exception.py", line 55, in inner
    response = get_response(request)
  File "/usr/local/lib/python3.8/dist-packages/django/core/handlers/base.py", line 197, in _get_response
    response = wrapped_callback(request, *callback_args, **callback_kwargs)
  File "/usr/local/lib/python3.8/dist-packages/django/views/decorators/csrf.py", line 56, in wrapper_view
    return view_func(*args, **kwargs)
  File "/usr/local/lib/python3.8/dist-packages/django/views/generic/base.py", line 104, in view
    return self.dispatch(request, *args, **kwargs)
  File "/usr/local/lib/python3.8/dist-packages/rest_framework/views.py", line 509, in dispatch
    response = self.handle_exception(exc)
  File "/usr/local/lib/python3.8/dist-packages/rest_framework/views.py", line 469, in handle_exception
    self.raise_uncaught_exception(exc)
  File "/usr/local/lib/python3.8/dist-packages/rest_framework/views.py", line 480, in raise_uncaught_exception
    raise exc
  File "/usr/local/lib/python3.8/dist-packages/rest_framework/views.py", line 506, in dispatch
    response = handler(request, *args, **kwargs)
  File "/usr/local/lib/python3.8/dist-packages/rest_framework/decorators.py", line 50, in handler
    return func(*args, **kwargs)
  File "/var/www/html/skytron_backend/Skytronsystem/skytron_api/views.py", line 106, in TagDevice2Vehicle
    vehicle_owner=request.data['vehicle_owner'],
  File "/usr/local/lib/python3.8/dist-packages/django/utils/datastructures.py", line 86, in __getitem__
    raise MultiValueDictKeyError(key)
django.utils.datastructures.MultiValueDictKeyError: 'vehicle_owner'
[07/Feb/2024 07:06:26] "POST /api/tag/TagDevice2Vehicle/ HTTP/1.1" 500 109028
Internal Server Error: /api/tag/TagDevice2Vehicle/
Traceback (most recent call last):
  File "/usr/local/lib/python3.8/dist-packages/django/core/handlers/exception.py", line 55, in inner
    response = get_response(request)
  File "/usr/local/lib/python3.8/dist-packages/django/core/handlers/base.py", line 197, in _get_response
    response = wrapped_callback(request, *callback_args, **callback_kwargs)
  File "/usr/local/lib/python3.8/dist-packages/django/views/decorators/csrf.py", line 56, in wrapper_view
    return view_func(*args, **kwargs)
  File "/usr/local/lib/python3.8/dist-packages/django/views/generic/base.py", line 104, in view
    return self.dispatch(request, *args, **kwargs)
  File "/usr/local/lib/python3.8/dist-packages/rest_framework/views.py", line 509, in dispatch
    response = self.handle_exception(exc)
  File "/usr/local/lib/python3.8/dist-packages/rest_framework/views.py", line 469, in handle_exception
    self.raise_uncaught_exception(exc)
  File "/usr/local/lib/python3.8/dist-packages/rest_framework/views.py", line 480, in raise_uncaught_exception
    raise exc
  File "/usr/local/lib/python3.8/dist-packages/rest_framework/views.py", line 506, in dispatch
    response = handler(request, *args, **kwargs)
  File "/usr/local/lib/python3.8/dist-packages/rest_framework/decorators.py", line 50, in handler
    return func(*args, **kwargs)
  File "/var/www/html/skytron_backend/Skytronsystem/skytron_api/views.py", line 104, in TagDevice2Vehicle
    device_tag = DeviceTag.objects.create(
  File "/usr/local/lib/python3.8/dist-packages/django/db/models/manager.py", line 87, in manager_method
    return getattr(self.get_queryset(), name)(*args, **kwargs)
  File "/usr/local/lib/python3.8/dist-packages/django/db/models/query.py", line 656, in create
    obj = self.model(**kwargs)
  File "/usr/local/lib/python3.8/dist-packages/django/db/models/base.py", line 543, in __init__
    _setattr(self, field.name, rel_obj)
  File "/usr/local/lib/python3.8/dist-packages/django/db/models/fields/related_descriptors.py", line 266, in __set__
    raise ValueError(
ValueError: Cannot assign "1": "DeviceTag.device" must be a "DeviceStock" instance.
[07/Feb/2024 07:07:02] "POST /api/tag/TagDevice2Vehicle/ HTTP/1.1" 500 120171
/var/www/html/skytron_backend/Skytronsystem/skytron_api/views.py changed, reloading.
Watching for file changes with StatReloader
Performing system checks...

System check identified no issues (0 silenced).
February 07, 2024 - 07:08:17
Django version 4.2.9, using settings 'Skytronsystem.settings'
Starting development server at http://0.0.0.0:2000/
Quit the server with CONTROL-C.

[07/Feb/2024 07:08:27] "POST /api/tag/TagDevice2Vehicle/ HTTP/1.1" 201 414
/var/www/html/skytron_backend/Skytronsystem/skytron_api/views.py changed, reloading.
Watching for file changes with StatReloader
Performing system checks...

System check identified no issues (0 silenced).
February 07, 2024 - 07:09:28
Django version 4.2.9, using settings 'Skytronsystem.settings'
Starting development server at http://0.0.0.0:2000/
Quit the server with CONTROL-C.

[07/Feb/2024 07:09:43] "POST /api/tag/TagDevice2Vehicle/ HTTP/1.1" 201 405
/var/www/html/skytron_backend/Skytronsystem/skytron_api/views.py changed, reloading.
Watching for file changes with StatReloader
Performing system checks...

System check identified no issues (0 silenced).
February 07, 2024 - 07:17:04
Django version 4.2.9, using settings 'Skytronsystem.settings'
Starting development server at http://0.0.0.0:2000/
Quit the server with CONTROL-C.

/var/www/html/skytron_backend/Skytronsystem/skytron_api/views.py changed, reloading.
Watching for file changes with StatReloader
Performing system checks...

System check identified no issues (0 silenced).
February 07, 2024 - 07:17:29
Django version 4.2.9, using settings 'Skytronsystem.settings'
Starting development server at http://0.0.0.0:2000/
Quit the server with CONTROL-C.

/var/www/html/skytron_backend/Skytronsystem/skytron_api/views.py changed, reloading.
Watching for file changes with StatReloader
Performing system checks...

System check identified no issues (0 silenced).
February 07, 2024 - 07:47:45
Django version 4.2.9, using settings 'Skytronsystem.settings'
Starting development server at http://0.0.0.0:2000/
Quit the server with CONTROL-C.

/var/www/html/skytron_backend/Skytronsystem/skytron_api/views.py changed, reloading.
Watching for file changes with StatReloader
Performing system checks...

System check identified no issues (0 silenced).
February 07, 2024 - 07:51:47
Django version 4.2.9, using settings 'Skytronsystem.settings'
Starting development server at http://0.0.0.0:2000/
Quit the server with CONTROL-C.

/var/www/html/skytron_backend/Skytronsystem/skytron_api/urls.py changed, reloading.
Watching for file changes with StatReloader
Performing system checks...

System check identified no issues (0 silenced).
February 07, 2024 - 07:55:31
Django version 4.2.9, using settings 'Skytronsystem.settings'
Starting development server at http://0.0.0.0:2000/
Quit the server with CONTROL-C.

/var/www/html/skytron_backend/Skytronsystem/skytron_api/urls.py changed, reloading.
Watching for file changes with StatReloader
Performing system checks...

System check identified no issues (0 silenced).
February 07, 2024 - 07:56:13
Django version 4.2.9, using settings 'Skytronsystem.settings'
Starting development server at http://0.0.0.0:2000/
Quit the server with CONTROL-C.

Internal Server Error: /api/tag/TagVerifyDealerOtp/
Traceback (most recent call last):
  File "/usr/local/lib/python3.8/dist-packages/django/db/backends/utils.py", line 89, in _execute
    return self.cursor.execute(sql, params)
  File "/usr/local/lib/python3.8/dist-packages/django/db/backends/sqlite3/base.py", line 328, in execute
    return super().execute(query, params)
sqlite3.IntegrityError: NOT NULL constraint failed: skytron_api_devicetag.tagged

The above exception was the direct cause of the following exception:

Traceback (most recent call last):
  File "/usr/local/lib/python3.8/dist-packages/django/core/handlers/exception.py", line 55, in inner
    response = get_response(request)
  File "/usr/local/lib/python3.8/dist-packages/django/core/handlers/base.py", line 197, in _get_response
    response = wrapped_callback(request, *callback_args, **callback_kwargs)
  File "/usr/local/lib/python3.8/dist-packages/django/views/decorators/csrf.py", line 56, in wrapper_view
    return view_func(*args, **kwargs)
  File "/usr/local/lib/python3.8/dist-packages/django/views/generic/base.py", line 104, in view
    return self.dispatch(request, *args, **kwargs)
  File "/usr/local/lib/python3.8/dist-packages/rest_framework/views.py", line 509, in dispatch
    response = self.handle_exception(exc)
  File "/usr/local/lib/python3.8/dist-packages/rest_framework/views.py", line 469, in handle_exception
    self.raise_uncaught_exception(exc)
  File "/usr/local/lib/python3.8/dist-packages/rest_framework/views.py", line 480, in raise_uncaught_exception
    raise exc
  File "/usr/local/lib/python3.8/dist-packages/rest_framework/views.py", line 506, in dispatch
    response = handler(request, *args, **kwargs)
  File "/usr/local/lib/python3.8/dist-packages/rest_framework/decorators.py", line 50, in handler
    return func(*args, **kwargs)
  File "/var/www/html/skytron_backend/Skytronsystem/skytron_api/views.py", line 176, in TagVerifyDealerOtp
    device_tag.save()
  File "/usr/local/lib/python3.8/dist-packages/django/db/models/base.py", line 814, in save
    self.save_base(
  File "/usr/local/lib/python3.8/dist-packages/django/db/models/base.py", line 877, in save_base
    updated = self._save_table(
  File "/usr/local/lib/python3.8/dist-packages/django/db/models/base.py", line 990, in _save_table
    updated = self._do_update(
  File "/usr/local/lib/python3.8/dist-packages/django/db/models/base.py", line 1054, in _do_update
    return filtered._update(values) > 0
  File "/usr/local/lib/python3.8/dist-packages/django/db/models/query.py", line 1231, in _update
    return query.get_compiler(self.db).execute_sql(CURSOR)
  File "/usr/local/lib/python3.8/dist-packages/django/db/models/sql/compiler.py", line 1984, in execute_sql
    cursor = super().execute_sql(result_type)
  File "/usr/local/lib/python3.8/dist-packages/django/db/models/sql/compiler.py", line 1562, in execute_sql
    cursor.execute(sql, params)
  File "/usr/local/lib/python3.8/dist-packages/django/db/backends/utils.py", line 102, in execute
    return super().execute(sql, params)
  File "/usr/local/lib/python3.8/dist-packages/django/db/backends/utils.py", line 67, in execute
    return self._execute_with_wrappers(
  File "/usr/local/lib/python3.8/dist-packages/django/db/backends/utils.py", line 80, in _execute_with_wrappers
    return executor(sql, params, many, context)
  File "/usr/local/lib/python3.8/dist-packages/django/db/backends/utils.py", line 89, in _execute
    return self.cursor.execute(sql, params)
  File "/usr/local/lib/python3.8/dist-packages/django/db/utils.py", line 91, in __exit__
    raise dj_exc_value.with_traceback(traceback) from exc_value
  File "/usr/local/lib/python3.8/dist-packages/django/db/backends/utils.py", line 89, in _execute
    return self.cursor.execute(sql, params)
  File "/usr/local/lib/python3.8/dist-packages/django/db/backends/sqlite3/base.py", line 328, in execute
    return super().execute(query, params)
django.db.utils.IntegrityError: NOT NULL constraint failed: skytron_api_devicetag.tagged
[07/Feb/2024 08:00:14] "POST /api/tag/TagVerifyDealerOtp/ HTTP/1.1" 500 179090
/var/www/html/skytron_backend/Skytronsystem/skytron_api/views.py changed, reloading.
Watching for file changes with StatReloader
Performing system checks...

System check identified no issues (0 silenced).
February 07, 2024 - 08:01:59
Django version 4.2.9, using settings 'Skytronsystem.settings'
Starting development server at http://0.0.0.0:2000/
Quit the server with CONTROL-C.

/var/www/html/skytron_backend/Skytronsystem/skytron_api/views.py changed, reloading.
Watching for file changes with StatReloader
Performing system checks...

System check identified no issues (0 silenced).
February 07, 2024 - 08:02:13
Django version 4.2.9, using settings 'Skytronsystem.settings'
Starting development server at http://0.0.0.0:2000/
Quit the server with CONTROL-C.

Internal Server Error: /api/tag/TagVerifyDealerOtp/
Traceback (most recent call last):
  File "/usr/local/lib/python3.8/dist-packages/django/core/handlers/exception.py", line 55, in inner
    response = get_response(request)
  File "/usr/local/lib/python3.8/dist-packages/django/core/handlers/base.py", line 197, in _get_response
    response = wrapped_callback(request, *callback_args, **callback_kwargs)
  File "/usr/local/lib/python3.8/dist-packages/django/views/decorators/csrf.py", line 56, in wrapper_view
    return view_func(*args, **kwargs)
  File "/usr/local/lib/python3.8/dist-packages/django/views/generic/base.py", line 104, in view
    return self.dispatch(request, *args, **kwargs)
  File "/usr/local/lib/python3.8/dist-packages/rest_framework/views.py", line 509, in dispatch
    response = self.handle_exception(exc)
  File "/usr/local/lib/python3.8/dist-packages/rest_framework/views.py", line 469, in handle_exception
    self.raise_uncaught_exception(exc)
  File "/usr/local/lib/python3.8/dist-packages/rest_framework/views.py", line 480, in raise_uncaught_exception
    raise exc
  File "/usr/local/lib/python3.8/dist-packages/rest_framework/views.py", line 506, in dispatch
    response = handler(request, *args, **kwargs)
  File "/usr/local/lib/python3.8/dist-packages/rest_framework/decorators.py", line 50, in handler
    return func(*args, **kwargs)
  File "/var/www/html/skytron_backend/Skytronsystem/skytron_api/views.py", line 172, in TagVerifyDealerOtp
    device_tag = get_object_or_404(DeviceTag, device_id=device_tag_id,  status='Dealer_OTP_Sent')
  File "/usr/local/lib/python3.8/dist-packages/django/shortcuts.py", line 85, in get_object_or_404
    return queryset.get(*args, **kwargs)
  File "/usr/local/lib/python3.8/dist-packages/django/db/models/query.py", line 640, in get
    raise self.model.MultipleObjectsReturned(
skytron_api.models.DeviceTag.MultipleObjectsReturned: get() returned more than one DeviceTag -- it returned 2!
[07/Feb/2024 08:02:17] "POST /api/tag/TagVerifyDealerOtp/ HTTP/1.1" 500 102217
Not Found: /api/tag/TagVerifyDealerOtp/
[07/Feb/2024 08:02:37] "POST /api/tag/TagVerifyDealerOtp/ HTTP/1.1" 404 23
/var/www/html/skytron_backend/Skytronsystem/skytron_api/views.py changed, reloading.
Watching for file changes with StatReloader
Performing system checks...

System check identified no issues (0 silenced).
February 07, 2024 - 08:03:40
Django version 4.2.9, using settings 'Skytronsystem.settings'
Starting development server at http://0.0.0.0:2000/
Quit the server with CONTROL-C.

Internal Server Error: /api/tag/TagVerifyDealerOtp/
Traceback (most recent call last):
  File "/usr/local/lib/python3.8/dist-packages/django/core/handlers/exception.py", line 55, in inner
    response = get_response(request)
  File "/usr/local/lib/python3.8/dist-packages/django/core/handlers/base.py", line 197, in _get_response
    response = wrapped_callback(request, *callback_args, **callback_kwargs)
  File "/usr/local/lib/python3.8/dist-packages/django/views/decorators/csrf.py", line 56, in wrapper_view
    return view_func(*args, **kwargs)
  File "/usr/local/lib/python3.8/dist-packages/django/views/generic/base.py", line 104, in view
    return self.dispatch(request, *args, **kwargs)
  File "/usr/local/lib/python3.8/dist-packages/rest_framework/views.py", line 509, in dispatch
    response = self.handle_exception(exc)
  File "/usr/local/lib/python3.8/dist-packages/rest_framework/views.py", line 469, in handle_exception
    self.raise_uncaught_exception(exc)
  File "/usr/local/lib/python3.8/dist-packages/rest_framework/views.py", line 480, in raise_uncaught_exception
    raise exc
  File "/usr/local/lib/python3.8/dist-packages/rest_framework/views.py", line 506, in dispatch
    response = handler(request, *args, **kwargs)
  File "/usr/local/lib/python3.8/dist-packages/rest_framework/decorators.py", line 50, in handler
    return func(*args, **kwargs)
  File "/var/www/html/skytron_backend/Skytronsystem/skytron_api/views.py", line 172, in TagVerifyDealerOtp
    device_tag = get_object_or_404(DeviceTag, device_id=device_tag_id,  status='Dealer_OTP_Sent')
  File "/usr/local/lib/python3.8/dist-packages/django/shortcuts.py", line 85, in get_object_or_404
    return queryset.get(*args, **kwargs)
  File "/usr/local/lib/python3.8/dist-packages/django/db/models/query.py", line 640, in get
    raise self.model.MultipleObjectsReturned(
skytron_api.models.DeviceTag.MultipleObjectsReturned: get() returned more than one DeviceTag -- it returned 2!
[07/Feb/2024 08:03:47] "POST /api/tag/TagVerifyDealerOtp/ HTTP/1.1" 500 102251
/var/www/html/skytron_backend/Skytronsystem/skytron_api/views.py changed, reloading.
Watching for file changes with StatReloader
Performing system checks...

System check identified no issues (0 silenced).
February 07, 2024 - 08:09:25
Django version 4.2.9, using settings 'Skytronsystem.settings'
Starting development server at http://0.0.0.0:2000/
Quit the server with CONTROL-C.

Internal Server Error: /api/tag/TagVerifyDealerOtp/
Traceback (most recent call last):
  File "/usr/local/lib/python3.8/dist-packages/django/core/handlers/exception.py", line 55, in inner
    response = get_response(request)
  File "/usr/local/lib/python3.8/dist-packages/django/core/handlers/base.py", line 197, in _get_response
    response = wrapped_callback(request, *callback_args, **callback_kwargs)
  File "/usr/local/lib/python3.8/dist-packages/django/views/decorators/csrf.py", line 56, in wrapper_view
    return view_func(*args, **kwargs)
  File "/usr/local/lib/python3.8/dist-packages/django/views/generic/base.py", line 104, in view
    return self.dispatch(request, *args, **kwargs)
  File "/usr/local/lib/python3.8/dist-packages/rest_framework/views.py", line 509, in dispatch
    response = self.handle_exception(exc)
  File "/usr/local/lib/python3.8/dist-packages/rest_framework/views.py", line 469, in handle_exception
    self.raise_uncaught_exception(exc)
  File "/usr/local/lib/python3.8/dist-packages/rest_framework/views.py", line 480, in raise_uncaught_exception
    raise exc
  File "/usr/local/lib/python3.8/dist-packages/rest_framework/views.py", line 506, in dispatch
    response = handler(request, *args, **kwargs)
  File "/usr/local/lib/python3.8/dist-packages/rest_framework/decorators.py", line 50, in handler
    return func(*args, **kwargs)
  File "/var/www/html/skytron_backend/Skytronsystem/skytron_api/views.py", line 174, in TagVerifyDealerOtp
    device_tag = device_tag.first()
AttributeError: 'DeviceTag' object has no attribute 'first'
[07/Feb/2024 08:09:35] "POST /api/tag/TagVerifyDealerOtp/ HTTP/1.1" 500 93538
/var/www/html/skytron_backend/Skytronsystem/skytron_api/views.py changed, reloading.
Watching for file changes with StatReloader
Performing system checks...

System check identified no issues (0 silenced).
February 07, 2024 - 08:10:18
Django version 4.2.9, using settings 'Skytronsystem.settings'
Starting development server at http://0.0.0.0:2000/
Quit the server with CONTROL-C.

Internal Server Error: /api/tag/TagVerifyDealerOtp/
Traceback (most recent call last):
  File "/usr/local/lib/python3.8/dist-packages/django/db/backends/utils.py", line 89, in _execute
    return self.cursor.execute(sql, params)
  File "/usr/local/lib/python3.8/dist-packages/django/db/backends/sqlite3/base.py", line 328, in execute
    return super().execute(query, params)
sqlite3.IntegrityError: NOT NULL constraint failed: skytron_api_devicetag.tagged

The above exception was the direct cause of the following exception:

Traceback (most recent call last):
  File "/usr/local/lib/python3.8/dist-packages/django/core/handlers/exception.py", line 55, in inner
    response = get_response(request)
  File "/usr/local/lib/python3.8/dist-packages/django/core/handlers/base.py", line 197, in _get_response
    response = wrapped_callback(request, *callback_args, **callback_kwargs)
  File "/usr/local/lib/python3.8/dist-packages/django/views/decorators/csrf.py", line 56, in wrapper_view
    return view_func(*args, **kwargs)
  File "/usr/local/lib/python3.8/dist-packages/django/views/generic/base.py", line 104, in view
    return self.dispatch(request, *args, **kwargs)
  File "/usr/local/lib/python3.8/dist-packages/rest_framework/views.py", line 509, in dispatch
    response = self.handle_exception(exc)
  File "/usr/local/lib/python3.8/dist-packages/rest_framework/views.py", line 469, in handle_exception
    self.raise_uncaught_exception(exc)
  File "/usr/local/lib/python3.8/dist-packages/rest_framework/views.py", line 480, in raise_uncaught_exception
    raise exc
  File "/usr/local/lib/python3.8/dist-packages/rest_framework/views.py", line 506, in dispatch
    response = handler(request, *args, **kwargs)
  File "/usr/local/lib/python3.8/dist-packages/rest_framework/decorators.py", line 50, in handler
    return func(*args, **kwargs)
  File "/var/www/html/skytron_backend/Skytronsystem/skytron_api/views.py", line 177, in TagVerifyDealerOtp
    device_tag.save()
  File "/usr/local/lib/python3.8/dist-packages/django/db/models/base.py", line 814, in save
    self.save_base(
  File "/usr/local/lib/python3.8/dist-packages/django/db/models/base.py", line 877, in save_base
    updated = self._save_table(
  File "/usr/local/lib/python3.8/dist-packages/django/db/models/base.py", line 990, in _save_table
    updated = self._do_update(
  File "/usr/local/lib/python3.8/dist-packages/django/db/models/base.py", line 1054, in _do_update
    return filtered._update(values) > 0
  File "/usr/local/lib/python3.8/dist-packages/django/db/models/query.py", line 1231, in _update
    return query.get_compiler(self.db).execute_sql(CURSOR)
  File "/usr/local/lib/python3.8/dist-packages/django/db/models/sql/compiler.py", line 1984, in execute_sql
    cursor = super().execute_sql(result_type)
  File "/usr/local/lib/python3.8/dist-packages/django/db/models/sql/compiler.py", line 1562, in execute_sql
    cursor.execute(sql, params)
  File "/usr/local/lib/python3.8/dist-packages/django/db/backends/utils.py", line 102, in execute
    return super().execute(sql, params)
  File "/usr/local/lib/python3.8/dist-packages/django/db/backends/utils.py", line 67, in execute
    return self._execute_with_wrappers(
  File "/usr/local/lib/python3.8/dist-packages/django/db/backends/utils.py", line 80, in _execute_with_wrappers
    return executor(sql, params, many, context)
  File "/usr/local/lib/python3.8/dist-packages/django/db/backends/utils.py", line 89, in _execute
    return self.cursor.execute(sql, params)
  File "/usr/local/lib/python3.8/dist-packages/django/db/utils.py", line 91, in __exit__
    raise dj_exc_value.with_traceback(traceback) from exc_value
  File "/usr/local/lib/python3.8/dist-packages/django/db/backends/utils.py", line 89, in _execute
    return self.cursor.execute(sql, params)
  File "/usr/local/lib/python3.8/dist-packages/django/db/backends/sqlite3/base.py", line 328, in execute
    return super().execute(query, params)
django.db.utils.IntegrityError: NOT NULL constraint failed: skytron_api_devicetag.tagged
[07/Feb/2024 08:10:23] "POST /api/tag/TagVerifyDealerOtp/ HTTP/1.1" 500 179183
/var/www/html/skytron_backend/Skytronsystem/skytron_api/views.py changed, reloading.
Watching for file changes with StatReloader
Performing system checks...

System check identified no issues (0 silenced).
February 07, 2024 - 08:11:06
Django version 4.2.9, using settings 'Skytronsystem.settings'
Starting development server at http://0.0.0.0:2000/
Quit the server with CONTROL-C.

Internal Server Error: /api/tag/TagVerifyDealerOtp/
Traceback (most recent call last):
  File "/usr/local/lib/python3.8/dist-packages/django/core/handlers/exception.py", line 55, in inner
    response = get_response(request)
  File "/usr/local/lib/python3.8/dist-packages/django/core/handlers/base.py", line 197, in _get_response
    response = wrapped_callback(request, *callback_args, **callback_kwargs)
  File "/usr/local/lib/python3.8/dist-packages/django/views/decorators/csrf.py", line 56, in wrapper_view
    return view_func(*args, **kwargs)
  File "/usr/local/lib/python3.8/dist-packages/django/views/generic/base.py", line 104, in view
    return self.dispatch(request, *args, **kwargs)
  File "/usr/local/lib/python3.8/dist-packages/rest_framework/views.py", line 509, in dispatch
    response = self.handle_exception(exc)
  File "/usr/local/lib/python3.8/dist-packages/rest_framework/views.py", line 469, in handle_exception
    self.raise_uncaught_exception(exc)
  File "/usr/local/lib/python3.8/dist-packages/rest_framework/views.py", line 480, in raise_uncaught_exception
    raise exc
  File "/usr/local/lib/python3.8/dist-packages/rest_framework/views.py", line 506, in dispatch
    response = handler(request, *args, **kwargs)
  File "/usr/local/lib/python3.8/dist-packages/rest_framework/decorators.py", line 50, in handler
    return func(*args, **kwargs)
  File "/var/www/html/skytron_backend/Skytronsystem/skytron_api/views.py", line 173, in TagVerifyDealerOtp
    device_tag = get_object_or_404(DeviceTag, device_id=device_tag_id,  status='Dealer_OTP_Sent')
  File "/usr/local/lib/python3.8/dist-packages/django/shortcuts.py", line 85, in get_object_or_404
    return queryset.get(*args, **kwargs)
  File "/usr/local/lib/python3.8/dist-packages/django/db/models/query.py", line 640, in get
    raise self.model.MultipleObjectsReturned(
skytron_api.models.DeviceTag.MultipleObjectsReturned: get() returned more than one DeviceTag -- it returned 2!
[07/Feb/2024 08:11:09] "POST /api/tag/TagVerifyDealerOtp/ HTTP/1.1" 500 102302
/var/www/html/skytron_backend/Skytronsystem/skytron_api/views.py changed, reloading.
Watching for file changes with StatReloader
Performing system checks...

System check identified no issues (0 silenced).
February 07, 2024 - 08:14:27
Django version 4.2.9, using settings 'Skytronsystem.settings'
Starting development server at http://0.0.0.0:2000/
Quit the server with CONTROL-C.

/var/www/html/skytron_backend/Skytronsystem/skytron_api/views.py changed, reloading.
Watching for file changes with StatReloader
Performing system checks...

System check identified no issues (0 silenced).
February 07, 2024 - 08:14:40
Django version 4.2.9, using settings 'Skytronsystem.settings'
Starting development server at http://0.0.0.0:2000/
Quit the server with CONTROL-C.

Internal Server Error: /api/tag/TagVerifyDealerOtp/
Traceback (most recent call last):
  File "/usr/local/lib/python3.8/dist-packages/django/db/backends/utils.py", line 89, in _execute
    return self.cursor.execute(sql, params)
  File "/usr/local/lib/python3.8/dist-packages/django/db/backends/sqlite3/base.py", line 328, in execute
    return super().execute(query, params)
sqlite3.IntegrityError: NOT NULL constraint failed: skytron_api_devicetag.tagged

The above exception was the direct cause of the following exception:

Traceback (most recent call last):
  File "/usr/local/lib/python3.8/dist-packages/django/core/handlers/exception.py", line 55, in inner
    response = get_response(request)
  File "/usr/local/lib/python3.8/dist-packages/django/core/handlers/base.py", line 197, in _get_response
    response = wrapped_callback(request, *callback_args, **callback_kwargs)
  File "/usr/local/lib/python3.8/dist-packages/django/views/decorators/csrf.py", line 56, in wrapper_view
    return view_func(*args, **kwargs)
  File "/usr/local/lib/python3.8/dist-packages/django/views/generic/base.py", line 104, in view
    return self.dispatch(request, *args, **kwargs)
  File "/usr/local/lib/python3.8/dist-packages/rest_framework/views.py", line 509, in dispatch
    response = self.handle_exception(exc)
  File "/usr/local/lib/python3.8/dist-packages/rest_framework/views.py", line 469, in handle_exception
    self.raise_uncaught_exception(exc)
  File "/usr/local/lib/python3.8/dist-packages/rest_framework/views.py", line 480, in raise_uncaught_exception
    raise exc
  File "/usr/local/lib/python3.8/dist-packages/rest_framework/views.py", line 506, in dispatch
    response = handler(request, *args, **kwargs)
  File "/usr/local/lib/python3.8/dist-packages/rest_framework/decorators.py", line 50, in handler
    return func(*args, **kwargs)
  File "/var/www/html/skytron_backend/Skytronsystem/skytron_api/views.py", line 177, in TagVerifyDealerOtp
    device_tag.save()
  File "/usr/local/lib/python3.8/dist-packages/django/db/models/base.py", line 814, in save
    self.save_base(
  File "/usr/local/lib/python3.8/dist-packages/django/db/models/base.py", line 877, in save_base
    updated = self._save_table(
  File "/usr/local/lib/python3.8/dist-packages/django/db/models/base.py", line 990, in _save_table
    updated = self._do_update(
  File "/usr/local/lib/python3.8/dist-packages/django/db/models/base.py", line 1054, in _do_update
    return filtered._update(values) > 0
  File "/usr/local/lib/python3.8/dist-packages/django/db/models/query.py", line 1231, in _update
    return query.get_compiler(self.db).execute_sql(CURSOR)
  File "/usr/local/lib/python3.8/dist-packages/django/db/models/sql/compiler.py", line 1984, in execute_sql
    cursor = super().execute_sql(result_type)
  File "/usr/local/lib/python3.8/dist-packages/django/db/models/sql/compiler.py", line 1562, in execute_sql
    cursor.execute(sql, params)
  File "/usr/local/lib/python3.8/dist-packages/django/db/backends/utils.py", line 102, in execute
    return super().execute(sql, params)
  File "/usr/local/lib/python3.8/dist-packages/django/db/backends/utils.py", line 67, in execute
    return self._execute_with_wrappers(
  File "/usr/local/lib/python3.8/dist-packages/django/db/backends/utils.py", line 80, in _execute_with_wrappers
    return executor(sql, params, many, context)
  File "/usr/local/lib/python3.8/dist-packages/django/db/backends/utils.py", line 89, in _execute
    return self.cursor.execute(sql, params)
  File "/usr/local/lib/python3.8/dist-packages/django/db/utils.py", line 91, in __exit__
    raise dj_exc_value.with_traceback(traceback) from exc_value
  File "/usr/local/lib/python3.8/dist-packages/django/db/backends/utils.py", line 89, in _execute
    return self.cursor.execute(sql, params)
  File "/usr/local/lib/python3.8/dist-packages/django/db/backends/sqlite3/base.py", line 328, in execute
    return super().execute(query, params)
django.db.utils.IntegrityError: NOT NULL constraint failed: skytron_api_devicetag.tagged
[07/Feb/2024 08:14:48] "POST /api/tag/TagVerifyDealerOtp/ HTTP/1.1" 500 179183
/var/www/html/skytron_backend/Skytronsystem/skytron_api/views.py changed, reloading.
Watching for file changes with StatReloader
Performing system checks...

System check identified no issues (0 silenced).
February 07, 2024 - 08:15:23
Django version 4.2.9, using settings 'Skytronsystem.settings'
Starting development server at http://0.0.0.0:2000/
Quit the server with CONTROL-C.

Internal Server Error: /api/tag/TagVerifyDealerOtp/
Traceback (most recent call last):
  File "/usr/local/lib/python3.8/dist-packages/django/db/backends/utils.py", line 89, in _execute
    return self.cursor.execute(sql, params)
  File "/usr/local/lib/python3.8/dist-packages/django/db/backends/sqlite3/base.py", line 328, in execute
    return super().execute(query, params)
sqlite3.IntegrityError: NOT NULL constraint failed: skytron_api_devicetag.tagged

The above exception was the direct cause of the following exception:

Traceback (most recent call last):
  File "/usr/local/lib/python3.8/dist-packages/django/core/handlers/exception.py", line 55, in inner
    response = get_response(request)
  File "/usr/local/lib/python3.8/dist-packages/django/core/handlers/base.py", line 197, in _get_response
    response = wrapped_callback(request, *callback_args, **callback_kwargs)
  File "/usr/local/lib/python3.8/dist-packages/django/views/decorators/csrf.py", line 56, in wrapper_view
    return view_func(*args, **kwargs)
  File "/usr/local/lib/python3.8/dist-packages/django/views/generic/base.py", line 104, in view
    return self.dispatch(request, *args, **kwargs)
  File "/usr/local/lib/python3.8/dist-packages/rest_framework/views.py", line 509, in dispatch
    response = self.handle_exception(exc)
  File "/usr/local/lib/python3.8/dist-packages/rest_framework/views.py", line 469, in handle_exception
    self.raise_uncaught_exception(exc)
  File "/usr/local/lib/python3.8/dist-packages/rest_framework/views.py", line 480, in raise_uncaught_exception
    raise exc
  File "/usr/local/lib/python3.8/dist-packages/rest_framework/views.py", line 506, in dispatch
    response = handler(request, *args, **kwargs)
  File "/usr/local/lib/python3.8/dist-packages/rest_framework/decorators.py", line 50, in handler
    return func(*args, **kwargs)
  File "/var/www/html/skytron_backend/Skytronsystem/skytron_api/views.py", line 177, in TagVerifyDealerOtp
    device_tag.save()
  File "/usr/local/lib/python3.8/dist-packages/django/db/models/base.py", line 814, in save
    self.save_base(
  File "/usr/local/lib/python3.8/dist-packages/django/db/models/base.py", line 877, in save_base
    updated = self._save_table(
  File "/usr/local/lib/python3.8/dist-packages/django/db/models/base.py", line 990, in _save_table
    updated = self._do_update(
  File "/usr/local/lib/python3.8/dist-packages/django/db/models/base.py", line 1054, in _do_update
    return filtered._update(values) > 0
  File "/usr/local/lib/python3.8/dist-packages/django/db/models/query.py", line 1231, in _update
    return query.get_compiler(self.db).execute_sql(CURSOR)
  File "/usr/local/lib/python3.8/dist-packages/django/db/models/sql/compiler.py", line 1984, in execute_sql
    cursor = super().execute_sql(result_type)
  File "/usr/local/lib/python3.8/dist-packages/django/db/models/sql/compiler.py", line 1562, in execute_sql
    cursor.execute(sql, params)
  File "/usr/local/lib/python3.8/dist-packages/django/db/backends/utils.py", line 102, in execute
    return super().execute(sql, params)
  File "/usr/local/lib/python3.8/dist-packages/django/db/backends/utils.py", line 67, in execute
    return self._execute_with_wrappers(
  File "/usr/local/lib/python3.8/dist-packages/django/db/backends/utils.py", line 80, in _execute_with_wrappers
    return executor(sql, params, many, context)
  File "/usr/local/lib/python3.8/dist-packages/django/db/backends/utils.py", line 89, in _execute
    return self.cursor.execute(sql, params)
  File "/usr/local/lib/python3.8/dist-packages/django/db/utils.py", line 91, in __exit__
    raise dj_exc_value.with_traceback(traceback) from exc_value
  File "/usr/local/lib/python3.8/dist-packages/django/db/backends/utils.py", line 89, in _execute
    return self.cursor.execute(sql, params)
  File "/usr/local/lib/python3.8/dist-packages/django/db/backends/sqlite3/base.py", line 328, in execute
    return super().execute(query, params)
django.db.utils.IntegrityError: NOT NULL constraint failed: skytron_api_devicetag.tagged
[07/Feb/2024 08:15:29] "POST /api/tag/TagVerifyDealerOtp/ HTTP/1.1" 500 179180
[07/Feb/2024 08:16:30] "POST /api/tag/TagVerifyDealerOtp/ HTTP/1.1" 200 47
/var/www/html/skytron_backend/Skytronsystem/skytron_api/views.py changed, reloading.
Watching for file changes with StatReloader
Performing system checks...

System check identified no issues (0 silenced).
February 07, 2024 - 08:16:58
Django version 4.2.9, using settings 'Skytronsystem.settings'
Starting development server at http://0.0.0.0:2000/
Quit the server with CONTROL-C.

[07/Feb/2024 08:17:27] "POST /api/tag/TagDevice2Vehicle/ HTTP/1.1" 201 405
Not Found: /api/tag/TagVerifyDealerOtp/
[07/Feb/2024 08:17:56] "POST /api/tag/TagVerifyDealerOtp/ HTTP/1.1" 404 23
/var/www/html/skytron_backend/Skytronsystem/skytron_api/views.py changed, reloading.
Watching for file changes with StatReloader
Performing system checks...

System check identified no issues (0 silenced).
February 07, 2024 - 08:19:09
Django version 4.2.9, using settings 'Skytronsystem.settings'
Starting development server at http://0.0.0.0:2000/
Quit the server with CONTROL-C.

Internal Server Error: /api/tag/TagVerifyDealerOtp/
Traceback (most recent call last):
  File "/usr/local/lib/python3.8/dist-packages/django/core/handlers/exception.py", line 55, in inner
    response = get_response(request)
  File "/usr/local/lib/python3.8/dist-packages/django/core/handlers/base.py", line 197, in _get_response
    response = wrapped_callback(request, *callback_args, **callback_kwargs)
  File "/usr/local/lib/python3.8/dist-packages/django/views/decorators/csrf.py", line 56, in wrapper_view
    return view_func(*args, **kwargs)
  File "/usr/local/lib/python3.8/dist-packages/django/views/generic/base.py", line 104, in view
    return self.dispatch(request, *args, **kwargs)
  File "/usr/local/lib/python3.8/dist-packages/rest_framework/views.py", line 509, in dispatch
    response = self.handle_exception(exc)
  File "/usr/local/lib/python3.8/dist-packages/rest_framework/views.py", line 469, in handle_exception
    self.raise_uncaught_exception(exc)
  File "/usr/local/lib/python3.8/dist-packages/rest_framework/views.py", line 480, in raise_uncaught_exception
    raise exc
  File "/usr/local/lib/python3.8/dist-packages/rest_framework/views.py", line 506, in dispatch
    response = handler(request, *args, **kwargs)
  File "/usr/local/lib/python3.8/dist-packages/rest_framework/decorators.py", line 50, in handler
    return func(*args, **kwargs)
  File "/var/www/html/skytron_backend/Skytronsystem/skytron_api/views.py", line 173, in TagVerifyDealerOtp
    device_tag = get_object_or_404(DeviceTag, device_id=device_tag_id,  status='Dealer_OTP_Sent')
  File "/usr/local/lib/python3.8/dist-packages/django/shortcuts.py", line 85, in get_object_or_404
    return queryset.get(*args, **kwargs)
  File "/usr/local/lib/python3.8/dist-packages/django/db/models/query.py", line 640, in get
    raise self.model.MultipleObjectsReturned(
skytron_api.models.DeviceTag.MultipleObjectsReturned: get() returned more than one DeviceTag -- it returned 2!
[07/Feb/2024 08:19:18] "POST /api/tag/TagVerifyDealerOtp/ HTTP/1.1" 500 102353
/var/www/html/skytron_backend/Skytronsystem/skytron_api/views.py changed, reloading.
Watching for file changes with StatReloader
Performing system checks...

System check identified no issues (0 silenced).
February 07, 2024 - 08:19:45
Django version 4.2.9, using settings 'Skytronsystem.settings'
Starting development server at http://0.0.0.0:2000/
Quit the server with CONTROL-C.

[07/Feb/2024 08:19:58] "POST /api/tag/TagVerifyDealerOtp/ HTTP/1.1" 200 47
Bad Request: /api/tag/TagVerifyDealerOtp/
[07/Feb/2024 08:20:23] "POST /api/tag/TagVerifyDealerOtp/ HTTP/1.1" 400 11
Method Not Allowed: /api/tag/TagAwaitingOwnerApproval/
[07/Feb/2024 08:22:20] "POST /api/tag/TagAwaitingOwnerApproval/ HTTP/1.1" 405 41
[07/Feb/2024 08:22:26] "GET /api/tag/TagAwaitingOwnerApproval/ HTTP/1.1" 200 667
/var/www/html/skytron_backend/Skytronsystem/skytron_api/views.py changed, reloading.
Watching for file changes with StatReloader
Performing system checks...

System check identified no issues (0 silenced).
February 07, 2024 - 08:26:59
Django version 4.2.9, using settings 'Skytronsystem.settings'
Starting development server at http://0.0.0.0:2000/
Quit the server with CONTROL-C.

/var/www/html/skytron_backend/Skytronsystem/skytron_api/models.py changed, reloading.
Watching for file changes with StatReloader
Performing system checks...

System check identified no issues (0 silenced).
February 07, 2024 - 08:27:52
Django version 4.2.9, using settings 'Skytronsystem.settings'
Starting development server at http://0.0.0.0:2000/
Quit the server with CONTROL-C.

/var/www/html/skytron_backend/Skytronsystem/skytron_api/views.py changed, reloading.
Watching for file changes with StatReloader
Performing system checks...

System check identified no issues (0 silenced).
February 07, 2024 - 08:27:56
Django version 4.2.9, using settings 'Skytronsystem.settings'
Starting development server at http://0.0.0.0:2000/
Quit the server with CONTROL-C.

Method Not Allowed: /api/tag/TagSendOwnerOtp/
[07/Feb/2024 08:28:23] "GET /api/tag/TagSendOwnerOtp/ HTTP/1.1" 405 40
[07/Feb/2024 08:28:31] "POST /api/tag/TagSendOwnerOtp/ HTTP/1.1" 200 42
[07/Feb/2024 08:29:55] "POST /api/tag/TagVerifyOwnerOtp/ HTTP/1.1" 200 47
/var/www/html/skytron_backend/Skytronsystem/skytron_api/views.py changed, reloading.
Watching for file changes with StatReloader
Performing system checks...

System check identified no issues (0 silenced).
February 07, 2024 - 08:30:35
Django version 4.2.9, using settings 'Skytronsystem.settings'
Starting development server at http://0.0.0.0:2000/
Quit the server with CONTROL-C.

Internal Server Error: /api/tag/TagVerifyOwnerOtp/
Traceback (most recent call last):
  File "/usr/local/lib/python3.8/dist-packages/django/core/handlers/exception.py", line 55, in inner
    response = get_response(request)
  File "/usr/local/lib/python3.8/dist-packages/django/core/handlers/base.py", line 197, in _get_response
    response = wrapped_callback(request, *callback_args, **callback_kwargs)
  File "/usr/local/lib/python3.8/dist-packages/django/views/decorators/csrf.py", line 56, in wrapper_view
    return view_func(*args, **kwargs)
  File "/usr/local/lib/python3.8/dist-packages/django/views/generic/base.py", line 104, in view
    return self.dispatch(request, *args, **kwargs)
  File "/usr/local/lib/python3.8/dist-packages/rest_framework/views.py", line 509, in dispatch
    response = self.handle_exception(exc)
  File "/usr/local/lib/python3.8/dist-packages/rest_framework/views.py", line 469, in handle_exception
    self.raise_uncaught_exception(exc)
  File "/usr/local/lib/python3.8/dist-packages/rest_framework/views.py", line 480, in raise_uncaught_exception
    raise exc
  File "/usr/local/lib/python3.8/dist-packages/rest_framework/views.py", line 506, in dispatch
    response = handler(request, *args, **kwargs)
  File "/usr/local/lib/python3.8/dist-packages/rest_framework/decorators.py", line 50, in handler
    return func(*args, **kwargs)
  File "/var/www/html/skytron_backend/Skytronsystem/skytron_api/views.py", line 164, in TagVerifyOwnerOtp
    device_tag.status = 'Owner_OTP_Verified'
AttributeError: 'NoneType' object has no attribute 'status'
[07/Feb/2024 08:30:44] "POST /api/tag/TagVerifyOwnerOtp/ HTTP/1.1" 500 93386
[07/Feb/2024 08:31:23] "GET /api/tag/TagAwaitingOwnerApproval/ HTTP/1.1" 200 334
[07/Feb/2024 13:04:03] code 400, message Bad request syntax ('\x00')
[07/Feb/2024 13:04:03] " " 400 -
/var/www/html/skytron_backend/Skytronsystem/skytron_api/urls.py changed, reloading.
Watching for file changes with StatReloader
Performing system checks...

Exception in thread django-main-thread:
Traceback (most recent call last):
  File "/usr/lib/python3.8/threading.py", line 932, in _bootstrap_inner
    self.run()
  File "/usr/lib/python3.8/threading.py", line 870, in run
    self._target(*self._args, **self._kwargs)
  File "/usr/local/lib/python3.8/dist-packages/django/utils/autoreload.py", line 64, in wrapper
    fn(*args, **kwargs)
  File "/usr/local/lib/python3.8/dist-packages/django/core/management/commands/runserver.py", line 133, in inner_run
    self.check(display_num_errors=True)
  File "/usr/local/lib/python3.8/dist-packages/django/core/management/base.py", line 485, in check
    all_issues = checks.run_checks(
  File "/usr/local/lib/python3.8/dist-packages/django/core/checks/registry.py", line 88, in run_checks
    new_errors = check(app_configs=app_configs, databases=databases)
  File "/usr/local/lib/python3.8/dist-packages/django/core/checks/urls.py", line 14, in check_url_config
    return check_resolver(resolver)
  File "/usr/local/lib/python3.8/dist-packages/django/core/checks/urls.py", line 24, in check_resolver
    return check_method()
  File "/usr/local/lib/python3.8/dist-packages/django/urls/resolvers.py", line 494, in check
    for pattern in self.url_patterns:
  File "/usr/local/lib/python3.8/dist-packages/django/utils/functional.py", line 57, in __get__
    res = instance.__dict__[self.name] = self.func(instance)
  File "/usr/local/lib/python3.8/dist-packages/django/urls/resolvers.py", line 715, in url_patterns
    patterns = getattr(self.urlconf_module, "urlpatterns", self.urlconf_module)
  File "/usr/local/lib/python3.8/dist-packages/django/utils/functional.py", line 57, in __get__
    res = instance.__dict__[self.name] = self.func(instance)
  File "/usr/local/lib/python3.8/dist-packages/django/urls/resolvers.py", line 708, in urlconf_module
    return import_module(self.urlconf_name)
  File "/usr/lib/python3.8/importlib/__init__.py", line 127, in import_module
    return _bootstrap._gcd_import(name[level:], package, level)
  File "<frozen importlib._bootstrap>", line 1014, in _gcd_import
  File "<frozen importlib._bootstrap>", line 991, in _find_and_load
  File "<frozen importlib._bootstrap>", line 975, in _find_and_load_unlocked
  File "<frozen importlib._bootstrap>", line 671, in _load_unlocked
  File "<frozen importlib._bootstrap_external>", line 848, in exec_module
  File "<frozen importlib._bootstrap>", line 219, in _call_with_frames_removed
  File "/var/www/html/skytron_backend/Skytronsystem/Skytronsystem/urls.py", line 24, in <module>
    path('api/', include('skytron_api.urls')),  # Include the skytron_api URLs
  File "/usr/local/lib/python3.8/dist-packages/django/urls/conf.py", line 38, in include
    urlconf_module = import_module(urlconf_module)
  File "/usr/lib/python3.8/importlib/__init__.py", line 127, in import_module
    return _bootstrap._gcd_import(name[level:], package, level)
  File "<frozen importlib._bootstrap>", line 1014, in _gcd_import
  File "<frozen importlib._bootstrap>", line 991, in _find_and_load
  File "<frozen importlib._bootstrap>", line 975, in _find_and_load_unlocked
  File "<frozen importlib._bootstrap>", line 671, in _load_unlocked
  File "<frozen importlib._bootstrap_external>", line 848, in exec_module
  File "<frozen importlib._bootstrap>", line 219, in _call_with_frames_removed
  File "/var/www/html/skytron_backend/Skytronsystem/skytron_api/urls.py", line 11, in <module>
    from .views import (
ImportError: cannot import name 'download_static_file' from 'skytron_api.views' (/var/www/html/skytron_backend/Skytronsystem/skytron_api/views.py)
/var/www/html/skytron_backend/Skytronsystem/skytron_api/views.py changed, reloading.
Watching for file changes with StatReloader
Performing system checks...

System check identified no issues (0 silenced).
February 07, 2024 - 13:12:04
Django version 4.2.9, using settings 'Skytronsystem.settings'
Starting development server at http://0.0.0.0:2000/
Quit the server with CONTROL-C.

Not Found: /api/devicestock/deviceStockBulkSample//
[07/Feb/2024 13:13:16] "GET /api/devicestock/deviceStockBulkSample// HTTP/1.1" 404 18360
Not Found: /api/devicestock/deviceStockBulkSample/
[07/Feb/2024 13:14:54] "GET /api/devicestock/deviceStockBulkSample/ HTTP/1.1" 404 15
Not Found: /api/devicestock/deviceStockBulkSample/
[07/Feb/2024 13:15:37] "GET /api/devicestock/deviceStockBulkSample/ HTTP/1.1" 404 15
/var/www/html/skytron_backend/Skytronsystem/skytron_api/views.py changed, reloading.
Watching for file changes with StatReloader
Performing system checks...

System check identified no issues (0 silenced).
February 07, 2024 - 13:20:38
Django version 4.2.9, using settings 'Skytronsystem.settings'
Starting development server at http://0.0.0.0:2000/
Quit the server with CONTROL-C.

/var/www/html/skytron_backend/Skytronsystem/skytron_api/views.py changed, reloading.
Watching for file changes with StatReloader
Performing system checks...

System check identified no issues (0 silenced).
February 07, 2024 - 13:21:12
Django version 4.2.9, using settings 'Skytronsystem.settings'
Starting development server at http://0.0.0.0:2000/
Quit the server with CONTROL-C.

Not Found: /api/devicestock/deviceStockBulkSample/
[07/Feb/2024 13:21:19] "GET /api/devicestock/deviceStockBulkSample/ HTTP/1.1" 404 15
/var/www/html/skytron_backend/Skytronsystem/skytron_api/views.py changed, reloading.
Watching for file changes with StatReloader
Performing system checks...

System check identified no issues (0 silenced).
February 07, 2024 - 13:22:02
Django version 4.2.9, using settings 'Skytronsystem.settings'
Starting development server at http://0.0.0.0:2000/
Quit the server with CONTROL-C.

[07/Feb/2024 13:22:09] "GET /api/devicestock/deviceStockBulkSample/ HTTP/1.1" 200 9312
[07/Feb/2024 13:22:24] "GET /api/devicestock/deviceStockBulkSample/ HTTP/1.1" 200 9312
